2021-12-07 11:06:02,439 - util.py[DEBUG]: Reading from /proc/uptime (quiet=False)
2021-12-07 11:06:02,439 - util.py[DEBUG]: Read 11 bytes from /proc/uptime
2021-12-07 11:06:02,440 - util.py[DEBUG]: Reading from /proc/uptime (quiet=False)
2021-12-07 11:06:02,440 - util.py[DEBUG]: Read 11 bytes from /proc/uptime
2021-12-07 11:06:02,441 - util.py[DEBUG]: Cloud-init v. 21.4-0ubuntu1~18.04.1 running 'init-local' at Tue, 07 Dec 2021 11:06:02 +0000. Up 11.65 seconds.
2021-12-07 11:06:02,441 - main.py[DEBUG]: No kernel command line url found.
2021-12-07 11:06:02,441 - main.py[DEBUG]: Closing stdin.
2021-12-07 11:06:02,445 - util.py[DEBUG]: Writing to /var/log/cloud-init.log - ab: [644] 0 bytes
2021-12-07 11:06:02,446 - util.py[DEBUG]: Changing the ownership of /var/log/cloud-init.log to 102:4
2021-12-07 11:06:02,446 - util.py[DEBUG]: Writing to /var/lib/cloud/data/python-version - wb: [644] 3 bytes
2021-12-07 11:06:02,447 - util.py[DEBUG]: Attempting to remove /var/lib/cloud/instance/boot-finished
2021-12-07 11:06:02,447 - util.py[DEBUG]: Attempting to remove /var/lib/cloud/data/no-net
2021-12-07 11:06:02,448 - handlers.py[DEBUG]: start: init-local/check-cache: attempting to read from cache [check]
2021-12-07 11:06:02,448 - util.py[DEBUG]: Reading from /var/lib/cloud/instance/obj.pkl (quiet=False)
2021-12-07 11:06:02,448 - stages.py[DEBUG]: no cache found
2021-12-07 11:06:02,448 - handlers.py[DEBUG]: finish: init-local/check-cache: SUCCESS: no cache found
2021-12-07 11:06:02,448 - util.py[DEBUG]: Attempting to remove /var/lib/cloud/instance
2021-12-07 11:06:02,451 - stages.py[DEBUG]: Using distro class <class 'cloudinit.distros.ubuntu.Distro'>
2021-12-07 11:06:02,452 - __init__.py[DEBUG]: Looking for data source in: ['Azure', 'None'], via packages ['', 'cloudinit.sources'] that matches dependencies ['FILESYSTEM']
2021-12-07 11:06:02,479 - __init__.py[DEBUG]: Searching for local data source in: ['DataSourceAzure']
2021-12-07 11:06:02,479 - handlers.py[DEBUG]: start: init-local/search-Azure: searching for local data from DataSourceAzure
2021-12-07 11:06:02,479 - __init__.py[DEBUG]: Seeing if we can get any data from <class 'cloudinit.sources.DataSourceAzure.DataSourceAzure'>
2021-12-07 11:06:02,480 - __init__.py[DEBUG]: Update datasource metadata and network config due to events: boot-new-instance
2021-12-07 11:06:02,480 - handlers.py[DEBUG]: start: azure-ds/_get_data: _get_data
2021-12-07 11:06:02,480 - handlers.py[DEBUG]: start: azure-ds/check-platform-viability: found azure asset tag
2021-12-07 11:06:02,480 - dmi.py[DEBUG]: querying dmi data /sys/class/dmi/id/chassis_asset_tag
2021-12-07 11:06:02,481 - handlers.py[DEBUG]: finish: azure-ds/check-platform-viability: SUCCESS: found azure asset tag
2021-12-07 11:06:02,481 - handlers.py[DEBUG]: start: azure-ds/get_boot_telemetry: get_boot_telemetry
2021-12-07 11:06:02,481 - azure.py[DEBUG]: Collecting boot telemetry
2021-12-07 11:06:02,481 - util.py[DEBUG]: Reading from /proc/uptime (quiet=False)
2021-12-07 11:06:02,481 - util.py[DEBUG]: Read 11 bytes from /proc/uptime
2021-12-07 11:06:02,481 - subp.py[DEBUG]: Running command ['/bin/systemctl', 'show', '-p', 'UserspaceTimestampMonotonic'] with allowed return codes [0] (shell=False, capture=True)
2021-12-07 11:06:02,489 - subp.py[DEBUG]: Running command ['/bin/systemctl', 'show', 'cloud-init-local', '-p', 'InactiveExitTimestampMonotonic'] with allowed return codes [0] (shell=False, capture=True)
2021-12-07 11:06:02,497 - handlers.py[DEBUG]: boot-telemetry: boot-telemetry: kernel_start=2021-12-07T11:05:50.761672Z user_start=2021-12-07T11:05:58.152781Z cloudinit_activation=2021-12-07T11:06:01.694734Z
2021-12-07 11:06:02,498 - handlers.py[DEBUG]: finish: azure-ds/get_boot_telemetry: SUCCESS: get_boot_telemetry
2021-12-07 11:06:02,498 - handlers.py[DEBUG]: start: azure-ds/get_system_info: get_system_info
2021-12-07 11:06:02,498 - handlers.py[DEBUG]: system-info: system information: cloudinit_version=21.4-0ubuntu1~18.04.1, kernel_version=5.4.0-1064-azure, variant=ubuntu, distro_name=ubuntu, distro_version=18.04, flavor=bionic, python_version=3.6.9
2021-12-07 11:06:02,498 - handlers.py[DEBUG]: finish: azure-ds/get_system_info: SUCCESS: get_system_info
2021-12-07 11:06:02,498 - handlers.py[DEBUG]: start: azure-ds/crawl_metadata: crawl_metadata
2021-12-07 11:06:02,498 - handlers.py[DEBUG]: start: azure-ds/list_possible_azure_ds: list_possible_azure_ds
2021-12-07 11:06:02,498 - handlers.py[DEBUG]: finish: azure-ds/list_possible_azure_ds: SUCCESS: list_possible_azure_ds
2021-12-07 11:06:02,498 - handlers.py[DEBUG]: start: azure-ds/load_azure_ds_dir: load_azure_ds_dir
2021-12-07 11:06:02,499 - handlers.py[DEBUG]: finish: azure-ds/load_azure_ds_dir: FAIL: load_azure_ds_dir
2021-12-07 11:06:02,499 - azure.py[DEBUG]: Did not find Azure data source in /var/lib/cloud/seed/azure
2021-12-07 11:06:02,499 - util.py[DEBUG]: Reading from /proc/mounts (quiet=False)
2021-12-07 11:06:02,499 - util.py[DEBUG]: Read 2296 bytes from /proc/mounts
2021-12-07 11:06:02,499 - util.py[DEBUG]: Fetched {'sysfs': {'fstype': 'sysfs', 'mountpoint': '/sys', 'opts': 'rw,nosuid,nodev,noexec,relatime'}, 'proc': {'fstype': 'proc', 'mountpoint': '/proc', 'opts': 'rw,nosuid,nodev,noexec,relatime'}, 'udev': {'fstype': 'devtmpfs', 'mountpoint': '/dev', 'opts': 'rw,nosuid,relatime,size=1738628k,nr_inodes=434657,mode=755'}, 'devpts': {'fstype': 'devpts', 'mountpoint': '/dev/pts', 'opts': 'rw,nosuid,noexec,relatime,gid=5,mode=620,ptmxmode=000'}, 'tmpfs': {'fstype': 'tmpfs', 'mountpoint': '/sys/fs/cgroup', 'opts': 'ro,nosuid,nodev,noexec,mode=755'}, '/dev/sda1': {'fstype': 'ext4', 'mountpoint': '/', 'opts': 'rw,relatime,discard'}, 'securityfs': {'fstype': 'securityfs', 'mountpoint': '/sys/kernel/security', 'opts': 'rw,nosuid,nodev,noexec,relatime'}, 'cgroup': {'fstype': 'cgroup', 'mountpoint': '/sys/fs/cgroup/perf_event', 'opts': 'rw,nosuid,nodev,noexec,relatime,perf_event'}, 'pstore': {'fstype': 'pstore', 'mountpoint': '/sys/fs/pstore', 'opts': 'rw,nosuid,nodev,noexec,relatime'}, 'systemd-1': {'fstype': 'autofs', 'mountpoint': '/proc/sys/fs/binfmt_misc', 'opts': 'rw,relatime,fd=33,pgrp=1,timeout=0,minproto=5,maxproto=5,direct,pipe_ino=13504'}, 'hugetlbfs': {'fstype': 'hugetlbfs', 'mountpoint': '/dev/hugepages', 'opts': 'rw,relatime,pagesize=2M'}, 'debugfs': {'fstype': 'debugfs', 'mountpoint': '/sys/kernel/debug', 'opts': 'rw,relatime'}, 'mqueue': {'fstype': 'mqueue', 'mountpoint': '/dev/mqueue', 'opts': 'rw,relatime'}, 'configfs': {'fstype': 'configfs', 'mountpoint': '/sys/kernel/config', 'opts': 'rw,relatime'}, 'fusectl': {'fstype': 'fusectl', 'mountpoint': '/sys/fs/fuse/connections', 'opts': 'rw,relatime'}, '/dev/sda15': {'fstype': 'vfat', 'mountpoint': '/boot/efi', 'opts': 'rw,relatime,fmask=0077,dmask=0077,codepage=437,iocharset=iso8859-1,shortname=mixed,errors=remount-ro'}} mounts from proc
2021-12-07 11:06:02,500 - subp.py[DEBUG]: Running command ['mount', '-o', 'ro', '-t', 'auto', '/dev/sr0', '/run/cloud-init/tmp/tmp97apj15r'] with allowed return codes [0] (shell=False, capture=True)
2021-12-07 11:06:02,610 - handlers.py[DEBUG]: start: azure-ds/load_azure_ds_dir: load_azure_ds_dir
2021-12-07 11:06:02,615 - handlers.py[DEBUG]: start: azure-ds/read_azure_ovf: read_azure_ovf
2021-12-07 11:06:02,622 - handlers.py[DEBUG]: start: azure-ds/_get_preprovisioning_cfgs: _get_preprovisioning_cfgs
2021-12-07 11:06:02,623 - handlers.py[DEBUG]: start: azure-ds/_get_preprovisionedvm_cfg_value: _get_preprovisionedvm_cfg_value
2021-12-07 11:06:02,623 - azure.py[INFO]: PreprovisionedVm: False
2021-12-07 11:06:02,623 - handlers.py[DEBUG]: finish: azure-ds/_get_preprovisionedvm_cfg_value: SUCCESS: _get_preprovisionedvm_cfg_value
2021-12-07 11:06:02,624 - handlers.py[DEBUG]: start: azure-ds/_get_preprovisionedvmtype_cfg_value: _get_preprovisionedvmtype_cfg_value
2021-12-07 11:06:02,624 - DataSourceAzure.py[DEBUG]: PreprovisionedVMType not found
2021-12-07 11:06:02,624 - handlers.py[DEBUG]: finish: azure-ds/_get_preprovisionedvmtype_cfg_value: SUCCESS: _get_preprovisionedvmtype_cfg_value
2021-12-07 11:06:02,624 - handlers.py[DEBUG]: finish: azure-ds/_get_preprovisioning_cfgs: SUCCESS: _get_preprovisioning_cfgs
2021-12-07 11:06:02,625 - handlers.py[DEBUG]: finish: azure-ds/read_azure_ovf: SUCCESS: read_azure_ovf
2021-12-07 11:06:02,625 - handlers.py[DEBUG]: finish: azure-ds/load_azure_ds_dir: SUCCESS: load_azure_ds_dir
2021-12-07 11:06:02,625 - subp.py[DEBUG]: Running command ['umount', '/run/cloud-init/tmp/tmp97apj15r'] with allowed return codes [0] (shell=False, capture=True)
2021-12-07 11:06:02,633 - azure.py[DEBUG]: Found provisioning metadata in /dev/sr0
2021-12-07 11:06:02,633 - util.py[DEBUG]: Reading from /sys/class/net/eth0/name_assign_type (quiet=False)
2021-12-07 11:06:02,634 - __init__.py[DEBUG]: Found unstable nic names: ['eth0']; calling udevadm settle
2021-12-07 11:06:02,634 - subp.py[DEBUG]: Running command ['udevadm', 'settle'] with allowed return codes [0] (shell=False, capture=True)
2021-12-07 11:06:02,654 - util.py[DEBUG]: Waiting for udev events to settle took 0.020 seconds
2021-12-07 11:06:02,655 - util.py[DEBUG]: Reading from /sys/class/net/eth0/carrier (quiet=False)
2021-12-07 11:06:02,655 - util.py[DEBUG]: Reading from /sys/class/net/eth0/dormant (quiet=False)
2021-12-07 11:06:02,655 - util.py[DEBUG]: Reading from /sys/class/net/eth0/operstate (quiet=False)
2021-12-07 11:06:02,655 - util.py[DEBUG]: Read 5 bytes from /sys/class/net/eth0/operstate
2021-12-07 11:06:02,655 - util.py[DEBUG]: Reading from /sys/class/net/eth0/address (quiet=False)
2021-12-07 11:06:02,655 - util.py[DEBUG]: Read 18 bytes from /sys/class/net/eth0/address
2021-12-07 11:06:02,655 - handlers.py[DEBUG]: start: azure-ds/get_imds_data_with_api_fallback: get_imds_data_with_api_fallback
2021-12-07 11:06:02,656 - DataSourceAzure.py[INFO]: Attempting IMDS api-version: 2021-08-01
2021-12-07 11:06:02,656 - handlers.py[DEBUG]: start: azure-ds/get_metadata_from_imds: get_metadata_from_imds
2021-12-07 11:06:02,656 - util.py[DEBUG]: Reading from /sys/class/net/eth0/operstate (quiet=False)
2021-12-07 11:06:02,656 - util.py[DEBUG]: Read 5 bytes from /sys/class/net/eth0/operstate
2021-12-07 11:06:02,657 - handlers.py[DEBUG]: start: azure-ds/obtain-dhcp-lease: obtain dhcp lease
2021-12-07 11:06:02,657 - dhcp.py[DEBUG]: Performing a dhcp discovery on eth0
2021-12-07 11:06:02,657 - util.py[DEBUG]: Copying /sbin/dhclient to /var/tmp/cloud-init/cloud-init-dhcp-14rmwspk/dhclient
2021-12-07 11:06:02,701 - subp.py[DEBUG]: Running command ['ip', 'link', 'set', 'dev', 'eth0', 'up'] with allowed return codes [0] (shell=False, capture=True)
2021-12-07 11:06:02,706 - subp.py[DEBUG]: Running command ['/var/tmp/cloud-init/cloud-init-dhcp-14rmwspk/dhclient', '-1', '-v', '-lf', '/var/tmp/cloud-init/cloud-init-dhcp-14rmwspk/dhcp.leases', '-pf', '/var/tmp/cloud-init/cloud-init-dhcp-14rmwspk/dhclient.pid', 'eth0', '-sf', '/bin/true'] with allowed return codes [0] (shell=False, capture=True)
2021-12-07 11:06:05,101 - util.py[DEBUG]: All files appeared after 0 seconds: ['/var/tmp/cloud-init/cloud-init-dhcp-14rmwspk/dhclient.pid', '/var/tmp/cloud-init/cloud-init-dhcp-14rmwspk/dhcp.leases']
2021-12-07 11:06:05,101 - util.py[DEBUG]: Reading from /var/tmp/cloud-init/cloud-init-dhcp-14rmwspk/dhclient.pid (quiet=False)
2021-12-07 11:06:05,101 - util.py[DEBUG]: Read 4 bytes from /var/tmp/cloud-init/cloud-init-dhcp-14rmwspk/dhclient.pid
2021-12-07 11:06:05,101 - util.py[DEBUG]: Reading from /proc/752/stat (quiet=True)
2021-12-07 11:06:05,101 - util.py[DEBUG]: Read 298 bytes from /proc/752/stat
2021-12-07 11:06:05,101 - dhcp.py[DEBUG]: killing dhclient with pid=752
2021-12-07 11:06:05,102 - azure.py[DEBUG]: dhclient output stream: 
2021-12-07 11:06:05,102 - azure.py[DEBUG]: dhclient error stream: Internet Systems Consortium DHCP Client 4.3.5
Copyright 2004-2016 Internet Systems Consortium.
All rights reserved.
For info, please visit https://www.isc.org/software/dhcp/

Listening on LPF/eth0/60:45:bd:87:66:71
Sending on   LPF/eth0/60:45:bd:87:66:71
Sending on   Socket/fallback
DHCPDISCOVER on eth0 to 255.255.255.255 port 67 interval 3 (xid=0xed7db90b)
DHCPREQUEST of 10.0.0.4 on eth0 to 255.255.255.255 port 67 (xid=0xbb97ded)
DHCPOFFER of 10.0.0.4 from 168.63.129.16
DHCPACK of 10.0.0.4 from 168.63.129.16
bound to 10.0.0.4 -- renewal in 4294967295 seconds.

2021-12-07 11:06:05,103 - util.py[DEBUG]: Reading from /var/tmp/cloud-init/cloud-init-dhcp-14rmwspk/dhcp.leases (quiet=False)
2021-12-07 11:06:05,103 - util.py[DEBUG]: Read 702 bytes from /var/tmp/cloud-init/cloud-init-dhcp-14rmwspk/dhcp.leases
2021-12-07 11:06:05,104 - dhcp.py[DEBUG]: Received dhcp lease on eth0 for 10.0.0.4/255.255.255.0
2021-12-07 11:06:05,104 - __init__.py[DEBUG]: Attempting setup of ephemeral network on eth0 with 10.0.0.4/24 brd 10.0.0.255
2021-12-07 11:06:05,104 - subp.py[DEBUG]: Running command ['ip', '-family', 'inet', 'addr', 'add', '10.0.0.4/24', 'broadcast', '10.0.0.255', 'dev', 'eth0'] with allowed return codes [0] (shell=False, capture=True)
2021-12-07 11:06:05,108 - subp.py[DEBUG]: Running command ['ip', '-family', 'inet', 'link', 'set', 'dev', 'eth0', 'up'] with allowed return codes [0] (shell=False, capture=True)
2021-12-07 11:06:05,111 - subp.py[DEBUG]: Running command ['ip', '-4', 'route', 'add', '0.0.0.0/0', 'via', '10.0.0.1', 'dev', 'eth0'] with allowed return codes [0] (shell=False, capture=True)
2021-12-07 11:06:05,114 - subp.py[DEBUG]: Running command ['ip', '-4', 'route', 'add', '168.63.129.16/32', 'via', '10.0.0.1', 'dev', 'eth0'] with allowed return codes [0] (shell=False, capture=True)
2021-12-07 11:06:05,117 - subp.py[DEBUG]: Running command ['ip', '-4', 'route', 'add', '169.254.169.254/32', 'via', '10.0.0.1', 'dev', 'eth0'] with allowed return codes [0] (shell=False, capture=True)
2021-12-07 11:06:05,120 - handlers.py[DEBUG]: finish: azure-ds/obtain-dhcp-lease: SUCCESS: obtain dhcp lease
2021-12-07 11:06:05,121 - handlers.py[DEBUG]: start: azure-ds/_get_metadata_from_imds: _get_metadata_from_imds
2021-12-07 11:06:05,121 - url_helper.py[DEBUG]: [0/1] open 'http://169.254.169.254/metadata/instance?api-version=2021-08-01&extended=true' with {'url': 'http://169.254.169.254/metadata/instance?api-version=2021-08-01&extended=true', 'allow_redirects': True, 'method': 'GET', 'timeout': 2.0, 'headers': {'User-Agent': 'Cloud-Init/21.4-0ubuntu1~18.04.1', 'Metadata': 'true'}} configuration
2021-12-07 11:06:05,137 - url_helper.py[DEBUG]: Read from http://169.254.169.254/metadata/instance?api-version=2021-08-01&extended=true (200, 2009b) after 1 attempts
2021-12-07 11:06:05,138 - handlers.py[DEBUG]: finish: azure-ds/_get_metadata_from_imds: SUCCESS: _get_metadata_from_imds
2021-12-07 11:06:05,138 - util.py[DEBUG]: Crawl of Azure Instance Metadata Service (IMDS) took 0.017 seconds
2021-12-07 11:06:05,138 - subp.py[DEBUG]: Running command ['ip', '-4', 'route', 'del', '169.254.169.254/32', 'via', '10.0.0.1', 'dev', 'eth0'] with allowed return codes [0] (shell=False, capture=True)
2021-12-07 11:06:05,141 - subp.py[DEBUG]: Running command ['ip', '-4', 'route', 'del', '168.63.129.16/32', 'via', '10.0.0.1', 'dev', 'eth0'] with allowed return codes [0] (shell=False, capture=True)
2021-12-07 11:06:05,144 - subp.py[DEBUG]: Running command ['ip', '-4', 'route', 'del', '0.0.0.0/0', 'via', '10.0.0.1', 'dev', 'eth0'] with allowed return codes [0] (shell=False, capture=True)
2021-12-07 11:06:05,147 - subp.py[DEBUG]: Running command ['ip', '-family', 'inet', 'link', 'set', 'dev', 'eth0', 'down'] with allowed return codes [0] (shell=False, capture=True)
2021-12-07 11:06:05,160 - subp.py[DEBUG]: Running command ['ip', '-family', 'inet', 'addr', 'del', '10.0.0.4/24', 'dev', 'eth0'] with allowed return codes [0] (shell=False, capture=True)
2021-12-07 11:06:05,163 - handlers.py[DEBUG]: finish: azure-ds/get_metadata_from_imds: SUCCESS: get_metadata_from_imds
2021-12-07 11:06:05,164 - handlers.py[DEBUG]: finish: azure-ds/get_imds_data_with_api_fallback: SUCCESS: get_imds_data_with_api_fallback
2021-12-07 11:06:05,164 - DataSourceAzure.py[DEBUG]: Username retrieved from IMDS: devGrafanaDashboard
2021-12-07 11:06:05,164 - DataSourceAzure.py[DEBUG]: Hostname retrieved from IMDS: grafana-vm
2021-12-07 11:06:05,164 - azure.py[DEBUG]: found datasource in /dev/sr0
2021-12-07 11:06:05,164 - handlers.py[DEBUG]: start: azure-ds/_get_random_seed: _get_random_seed
2021-12-07 11:06:05,165 - util.py[DEBUG]: Reading from /sys/firmware/acpi/tables/OEM0 (quiet=True)
2021-12-07 11:06:05,165 - util.py[DEBUG]: Read 100 bytes from /sys/firmware/acpi/tables/OEM0
2021-12-07 11:06:05,165 - handlers.py[DEBUG]: finish: azure-ds/_get_random_seed: SUCCESS: _get_random_seed
2021-12-07 11:06:05,165 - dmi.py[DEBUG]: querying dmi data /sys/class/dmi/id/product_uuid
2021-12-07 11:06:05,165 - handlers.py[DEBUG]: finish: azure-ds/crawl_metadata: SUCCESS: crawl_metadata
2021-12-07 11:06:05,165 - util.py[DEBUG]: Crawl of metadata service took 2.667 seconds
2021-12-07 11:06:05,165 - handlers.py[DEBUG]: start: azure-ds/maybe_remove_ubuntu_network_config_scripts: maybe_remove_ubuntu_network_config_scripts
2021-12-07 11:06:05,165 - DataSourceAzure.py[INFO]: Removing Ubuntu extended network scripts because cloud-init updates Azure network configuration on the following events: ['boot', 'boot-legacy'].
2021-12-07 11:06:05,166 - util.py[DEBUG]: Attempting to remove /etc/netplan/90-hotplug-azure.yaml
2021-12-07 11:06:05,166 - handlers.py[DEBUG]: finish: azure-ds/maybe_remove_ubuntu_network_config_scripts: SUCCESS: maybe_remove_ubuntu_network_config_scripts
2021-12-07 11:06:05,167 - azure.py[DEBUG]: Ephemeral resource disk '/dev/disk/cloud/azure_resource' exists. Merging default Azure cloud ephemeral disk configs.
2021-12-07 11:06:05,167 - handlers.py[DEBUG]: start: azure-ds/write_files: write_files
2021-12-07 11:06:05,169 - util.py[DEBUG]: Writing to /var/lib/waagent/ovf-env.xml - wb: [600] 1307 bytes
2021-12-07 11:06:05,170 - handlers.py[DEBUG]: finish: azure-ds/write_files: SUCCESS: write_files
2021-12-07 11:06:05,170 - handlers.py[DEBUG]: finish: azure-ds/_get_data: SUCCESS: _get_data
2021-12-07 11:06:05,170 - handlers.py[DEBUG]: start: azure-ds/get_public_ssh_keys: get_public_ssh_keys
2021-12-07 11:06:05,171 - DataSourceAzure.py[DEBUG]: Retrieving public SSH keys
2021-12-07 11:06:05,171 - DataSourceAzure.py[DEBUG]: Attempting to get SSH keys from IMDS
2021-12-07 11:06:05,171 - azure.py[DEBUG]: Retrieved 0 keys from IMDS
2021-12-07 11:06:05,171 - handlers.py[DEBUG]: finish: azure-ds/get_public_ssh_keys: SUCCESS: get_public_ssh_keys
2021-12-07 11:06:05,174 - atomic_helper.py[DEBUG]: Atomically writing to file /run/cloud-init/instance-data-sensitive.json (via temporary file /run/cloud-init/tmpkwavxlmo) - w: [600] 8093 bytes/chars
2021-12-07 11:06:05,175 - atomic_helper.py[DEBUG]: Atomically writing to file /run/cloud-init/instance-data.json (via temporary file /run/cloud-init/tmpkj3db1pq) - w: [644] 4709 bytes/chars
2021-12-07 11:06:05,175 - handlers.py[DEBUG]: finish: init-local/search-Azure: SUCCESS: found local data from DataSourceAzure
2021-12-07 11:06:05,175 - stages.py[INFO]: Loaded datasource DataSourceAzure - DataSourceAzure [seed=/dev/sr0]
2021-12-07 11:06:05,176 - util.py[DEBUG]: Reading from /etc/cloud/cloud.cfg (quiet=False)
2021-12-07 11:06:05,176 - util.py[DEBUG]: Read 3747 bytes from /etc/cloud/cloud.cfg
2021-12-07 11:06:05,176 - util.py[DEBUG]: Attempting to load yaml from string of length 3747 with allowed root types (<class 'dict'>,)
2021-12-07 11:06:05,189 - util.py[DEBUG]: Reading from /etc/cloud/cloud.cfg.d/90_dpkg.cfg (quiet=False)
2021-12-07 11:06:05,189 - util.py[DEBUG]: Read 82 bytes from /etc/cloud/cloud.cfg.d/90_dpkg.cfg
2021-12-07 11:06:05,189 - util.py[DEBUG]: Attempting to load yaml from string of length 82 with allowed root types (<class 'dict'>,)
2021-12-07 11:06:05,189 - util.py[DEBUG]: Reading from /etc/cloud/cloud.cfg.d/90-azure.cfg (quiet=False)
2021-12-07 11:06:05,190 - util.py[DEBUG]: Read 535 bytes from /etc/cloud/cloud.cfg.d/90-azure.cfg
2021-12-07 11:06:05,190 - util.py[DEBUG]: Attempting to load yaml from string of length 535 with allowed root types (<class 'dict'>,)
2021-12-07 11:06:05,192 - util.py[DEBUG]: Reading from /etc/cloud/cloud.cfg.d/10-azure-kvp.cfg (quiet=False)
2021-12-07 11:06:05,192 - util.py[DEBUG]: Read 143 bytes from /etc/cloud/cloud.cfg.d/10-azure-kvp.cfg
2021-12-07 11:06:05,192 - util.py[DEBUG]: Attempting to load yaml from string of length 143 with allowed root types (<class 'dict'>,)
2021-12-07 11:06:05,193 - util.py[DEBUG]: Reading from /etc/cloud/cloud.cfg.d/05_logging.cfg (quiet=False)
2021-12-07 11:06:05,193 - util.py[DEBUG]: Read 2070 bytes from /etc/cloud/cloud.cfg.d/05_logging.cfg
2021-12-07 11:06:05,193 - util.py[DEBUG]: Attempting to load yaml from string of length 2070 with allowed root types (<class 'dict'>,)
2021-12-07 11:06:05,197 - util.py[DEBUG]: Reading from /run/cloud-init/cloud.cfg (quiet=False)
2021-12-07 11:06:05,197 - util.py[DEBUG]: Read 33 bytes from /run/cloud-init/cloud.cfg
2021-12-07 11:06:05,197 - util.py[DEBUG]: Attempting to load yaml from string of length 33 with allowed root types (<class 'dict'>,)
2021-12-07 11:06:05,197 - util.py[DEBUG]: Attempting to load yaml from string of length 0 with allowed root types (<class 'dict'>,)
2021-12-07 11:06:05,197 - util.py[DEBUG]: loaded blob returned None, returning default.
2021-12-07 11:06:05,198 - util.py[DEBUG]: Attempting to remove /var/lib/cloud/instance
2021-12-07 11:06:05,198 - util.py[DEBUG]: Creating symbolic link from '/var/lib/cloud/instance' => '/var/lib/cloud/instances/9d5276fc-2736-a348-9ee7-95af558790ea'
2021-12-07 11:06:05,199 - util.py[DEBUG]: Reading from /var/lib/cloud/instances/9d5276fc-2736-a348-9ee7-95af558790ea/datasource (quiet=False)
2021-12-07 11:06:05,199 - util.py[DEBUG]: Writing to /var/lib/cloud/instances/9d5276fc-2736-a348-9ee7-95af558790ea/datasource - wb: [644] 49 bytes
2021-12-07 11:06:05,200 - util.py[DEBUG]: Writing to /var/lib/cloud/data/previous-datasource - wb: [644] 49 bytes
2021-12-07 11:06:05,200 - util.py[DEBUG]: Reading from /var/lib/cloud/data/instance-id (quiet=False)
2021-12-07 11:06:05,200 - stages.py[DEBUG]: previous iid found to be NO_PREVIOUS_INSTANCE_ID
2021-12-07 11:06:05,200 - util.py[DEBUG]: Writing to /var/lib/cloud/data/instance-id - wb: [644] 37 bytes
2021-12-07 11:06:05,201 - util.py[DEBUG]: Writing to /run/cloud-init/.instance-id - wb: [644] 37 bytes
2021-12-07 11:06:05,201 - util.py[DEBUG]: Writing to /var/lib/cloud/data/previous-instance-id - wb: [644] 24 bytes
2021-12-07 11:06:05,202 - util.py[DEBUG]: Writing to /var/lib/cloud/instance/obj.pkl - wb: [400] 10757 bytes
2021-12-07 11:06:05,202 - main.py[DEBUG]: [local] init will now be targeting instance id: 9d5276fc-2736-a348-9ee7-95af558790ea. new=True
2021-12-07 11:06:05,203 - util.py[DEBUG]: Reading from /etc/cloud/cloud.cfg (quiet=False)
2021-12-07 11:06:05,203 - util.py[DEBUG]: Read 3747 bytes from /etc/cloud/cloud.cfg
2021-12-07 11:06:05,203 - util.py[DEBUG]: Attempting to load yaml from string of length 3747 with allowed root types (<class 'dict'>,)
2021-12-07 11:06:05,215 - util.py[DEBUG]: Reading from /etc/cloud/cloud.cfg.d/90_dpkg.cfg (quiet=False)
2021-12-07 11:06:05,215 - util.py[DEBUG]: Read 82 bytes from /etc/cloud/cloud.cfg.d/90_dpkg.cfg
2021-12-07 11:06:05,215 - util.py[DEBUG]: Attempting to load yaml from string of length 82 with allowed root types (<class 'dict'>,)
2021-12-07 11:06:05,216 - util.py[DEBUG]: Reading from /etc/cloud/cloud.cfg.d/90-azure.cfg (quiet=False)
2021-12-07 11:06:05,216 - util.py[DEBUG]: Read 535 bytes from /etc/cloud/cloud.cfg.d/90-azure.cfg
2021-12-07 11:06:05,216 - util.py[DEBUG]: Attempting to load yaml from string of length 535 with allowed root types (<class 'dict'>,)
2021-12-07 11:06:05,219 - util.py[DEBUG]: Reading from /etc/cloud/cloud.cfg.d/10-azure-kvp.cfg (quiet=False)
2021-12-07 11:06:05,219 - util.py[DEBUG]: Read 143 bytes from /etc/cloud/cloud.cfg.d/10-azure-kvp.cfg
2021-12-07 11:06:05,219 - util.py[DEBUG]: Attempting to load yaml from string of length 143 with allowed root types (<class 'dict'>,)
2021-12-07 11:06:05,220 - util.py[DEBUG]: Reading from /etc/cloud/cloud.cfg.d/05_logging.cfg (quiet=False)
2021-12-07 11:06:05,220 - util.py[DEBUG]: Read 2070 bytes from /etc/cloud/cloud.cfg.d/05_logging.cfg
2021-12-07 11:06:05,220 - util.py[DEBUG]: Attempting to load yaml from string of length 2070 with allowed root types (<class 'dict'>,)
2021-12-07 11:06:05,223 - util.py[DEBUG]: Reading from /run/cloud-init/cloud.cfg (quiet=False)
2021-12-07 11:06:05,224 - util.py[DEBUG]: Read 33 bytes from /run/cloud-init/cloud.cfg
2021-12-07 11:06:05,224 - util.py[DEBUG]: Attempting to load yaml from string of length 33 with allowed root types (<class 'dict'>,)
2021-12-07 11:06:05,224 - util.py[DEBUG]: Attempting to load yaml from string of length 0 with allowed root types (<class 'dict'>,)
2021-12-07 11:06:05,224 - util.py[DEBUG]: loaded blob returned None, returning default.
2021-12-07 11:06:05,225 - stages.py[DEBUG]: Using distro class <class 'cloudinit.distros.ubuntu.Distro'>
2021-12-07 11:06:05,226 - cc_set_hostname.py[DEBUG]: Setting the hostname to grafana-vm (grafana-vm)
2021-12-07 11:06:05,226 - util.py[DEBUG]: Reading from /etc/hostname (quiet=False)
2021-12-07 11:06:05,226 - util.py[DEBUG]: Read 7 bytes from /etc/hostname
2021-12-07 11:06:05,226 - util.py[DEBUG]: Writing to /etc/hostname - wb: [644] 11 bytes
2021-12-07 11:06:05,227 - __init__.py[DEBUG]: Non-persistently setting the system hostname to grafana-vm
2021-12-07 11:06:05,227 - subp.py[DEBUG]: Running command ['hostname', 'grafana-vm'] with allowed return codes [0] (shell=False, capture=True)
2021-12-07 11:06:05,231 - atomic_helper.py[DEBUG]: Atomically writing to file /var/lib/cloud/data/set-hostname (via temporary file /var/lib/cloud/data/tmp_gxr3xci) - w: [644] 53 bytes/chars
2021-12-07 11:06:05,232 - util.py[DEBUG]: Reading from /sys/class/net/eth0/address (quiet=False)
2021-12-07 11:06:05,232 - util.py[DEBUG]: Read 18 bytes from /sys/class/net/eth0/address
2021-12-07 11:06:05,232 - util.py[DEBUG]: Reading from /sys/class/net/lo/address (quiet=False)
2021-12-07 11:06:05,232 - util.py[DEBUG]: Read 18 bytes from /sys/class/net/lo/address
2021-12-07 11:06:05,233 - handlers.py[DEBUG]: start: azure-ds/parse_network_config: parse_network_config
2021-12-07 11:06:05,233 - handlers.py[DEBUG]: start: azure-ds/_generate_network_config_from_imds_metadata: _generate_network_config_from_imds_metadata
2021-12-07 11:06:05,233 - handlers.py[DEBUG]: finish: azure-ds/_generate_network_config_from_imds_metadata: SUCCESS: _generate_network_config_from_imds_metadata
2021-12-07 11:06:05,234 - handlers.py[DEBUG]: finish: azure-ds/parse_network_config: SUCCESS: parse_network_config
2021-12-07 11:06:05,234 - util.py[DEBUG]: Reading from /sys/class/net/eth0/address (quiet=False)
2021-12-07 11:06:05,234 - util.py[DEBUG]: Read 18 bytes from /sys/class/net/eth0/address
2021-12-07 11:06:05,234 - util.py[DEBUG]: Reading from /sys/class/net/lo/address (quiet=False)
2021-12-07 11:06:05,234 - util.py[DEBUG]: Read 18 bytes from /sys/class/net/lo/address
2021-12-07 11:06:05,235 - util.py[DEBUG]: Reading from /sys/class/net/eth0/device/device (quiet=False)
2021-12-07 11:06:05,235 - util.py[DEBUG]: Read 4 bytes from /sys/class/net/eth0/device/device
2021-12-07 11:06:05,235 - util.py[DEBUG]: Reading from /sys/class/net/eth0/addr_assign_type (quiet=False)
2021-12-07 11:06:05,235 - util.py[DEBUG]: Read 2 bytes from /sys/class/net/eth0/addr_assign_type
2021-12-07 11:06:05,235 - util.py[DEBUG]: Reading from /sys/class/net/eth0/uevent (quiet=False)
2021-12-07 11:06:05,235 - util.py[DEBUG]: Read 25 bytes from /sys/class/net/eth0/uevent
2021-12-07 11:06:05,235 - util.py[DEBUG]: Reading from /sys/class/net/eth0/address (quiet=False)
2021-12-07 11:06:05,236 - util.py[DEBUG]: Read 18 bytes from /sys/class/net/eth0/address
2021-12-07 11:06:05,236 - __init__.py[DEBUG]: ovs-vsctl not in PATH; not detecting Open vSwitch interfaces
2021-12-07 11:06:05,236 - util.py[DEBUG]: Reading from /sys/class/net/eth0/device/device (quiet=False)
2021-12-07 11:06:05,236 - util.py[DEBUG]: Read 4 bytes from /sys/class/net/eth0/device/device
2021-12-07 11:06:05,236 - util.py[DEBUG]: Reading from /sys/class/net/lo/addr_assign_type (quiet=False)
2021-12-07 11:06:05,236 - util.py[DEBUG]: Read 2 bytes from /sys/class/net/lo/addr_assign_type
2021-12-07 11:06:05,236 - util.py[DEBUG]: Reading from /sys/class/net/lo/uevent (quiet=False)
2021-12-07 11:06:05,236 - util.py[DEBUG]: Read 23 bytes from /sys/class/net/lo/uevent
2021-12-07 11:06:05,236 - util.py[DEBUG]: Reading from /sys/class/net/lo/address (quiet=False)
2021-12-07 11:06:05,236 - util.py[DEBUG]: Read 18 bytes from /sys/class/net/lo/address
2021-12-07 11:06:05,237 - util.py[DEBUG]: Reading from /sys/class/net/lo/device/device (quiet=False)
2021-12-07 11:06:05,237 - util.py[DEBUG]: Reading from /sys/class/net/eth0/type (quiet=False)
2021-12-07 11:06:05,237 - util.py[DEBUG]: Read 2 bytes from /sys/class/net/eth0/type
2021-12-07 11:06:05,237 - util.py[DEBUG]: Reading from /sys/class/net/lo/type (quiet=False)
2021-12-07 11:06:05,237 - util.py[DEBUG]: Read 4 bytes from /sys/class/net/lo/type
2021-12-07 11:06:05,237 - networking.py[DEBUG]: net: all expected physical devices present
2021-12-07 11:06:05,237 - stages.py[DEBUG]: applying net config names for {'version': 2, 'ethernets': {'eth0': {'dhcp4': True, 'dhcp4-overrides': {'route-metric': 100}, 'dhcp6': False, 'match': {'macaddress': '60:45:bd:87:66:71', 'driver': 'hv_netvsc'}, 'set-name': 'eth0'}}}
2021-12-07 11:06:05,237 - util.py[DEBUG]: Reading from /sys/class/net/eth0/device/device (quiet=False)
2021-12-07 11:06:05,237 - util.py[DEBUG]: Read 4 bytes from /sys/class/net/eth0/device/device
2021-12-07 11:06:05,237 - util.py[DEBUG]: Reading from /sys/class/net/eth0/addr_assign_type (quiet=False)
2021-12-07 11:06:05,238 - util.py[DEBUG]: Read 2 bytes from /sys/class/net/eth0/addr_assign_type
2021-12-07 11:06:05,238 - util.py[DEBUG]: Reading from /sys/class/net/eth0/uevent (quiet=False)
2021-12-07 11:06:05,238 - util.py[DEBUG]: Read 25 bytes from /sys/class/net/eth0/uevent
2021-12-07 11:06:05,238 - util.py[DEBUG]: Reading from /sys/class/net/eth0/address (quiet=False)
2021-12-07 11:06:05,238 - util.py[DEBUG]: Read 18 bytes from /sys/class/net/eth0/address
2021-12-07 11:06:05,238 - util.py[DEBUG]: Reading from /sys/class/net/eth0/device/device (quiet=False)
2021-12-07 11:06:05,238 - util.py[DEBUG]: Read 4 bytes from /sys/class/net/eth0/device/device
2021-12-07 11:06:05,238 - util.py[DEBUG]: Reading from /sys/class/net/lo/addr_assign_type (quiet=False)
2021-12-07 11:06:05,238 - util.py[DEBUG]: Read 2 bytes from /sys/class/net/lo/addr_assign_type
2021-12-07 11:06:05,238 - util.py[DEBUG]: Reading from /sys/class/net/lo/uevent (quiet=False)
2021-12-07 11:06:05,238 - util.py[DEBUG]: Read 23 bytes from /sys/class/net/lo/uevent
2021-12-07 11:06:05,238 - util.py[DEBUG]: Reading from /sys/class/net/lo/address (quiet=False)
2021-12-07 11:06:05,239 - util.py[DEBUG]: Read 18 bytes from /sys/class/net/lo/address
2021-12-07 11:06:05,239 - util.py[DEBUG]: Reading from /sys/class/net/lo/device/device (quiet=False)
2021-12-07 11:06:05,239 - util.py[DEBUG]: Reading from /sys/class/net/eth0/operstate (quiet=False)
2021-12-07 11:06:05,239 - util.py[DEBUG]: Read 5 bytes from /sys/class/net/eth0/operstate
2021-12-07 11:06:05,239 - util.py[DEBUG]: Reading from /sys/class/net/lo/operstate (quiet=False)
2021-12-07 11:06:05,239 - util.py[DEBUG]: Read 8 bytes from /sys/class/net/lo/operstate
2021-12-07 11:06:05,239 - subp.py[DEBUG]: Running command ['ip', '-6', 'addr', 'show', 'permanent', 'scope', 'global'] with allowed return codes [0] (shell=False, capture=True)
2021-12-07 11:06:05,243 - subp.py[DEBUG]: Running command ['ip', '-4', 'addr', 'show'] with allowed return codes [0] (shell=False, capture=True)
2021-12-07 11:06:05,246 - __init__.py[DEBUG]: Detected interfaces {'eth0': {'downable': True, 'device_id': '0x3', 'driver': 'hv_netvsc', 'mac': '60:45:bd:87:66:71', 'name': 'eth0', 'up': False}, 'lo': {'downable': False, 'device_id': None, 'driver': None, 'mac': '00:00:00:00:00:00', 'name': 'lo', 'up': True}}
2021-12-07 11:06:05,246 - __init__.py[DEBUG]: no work necessary for renaming of [['60:45:bd:87:66:71', 'eth0', 'hv_netvsc', '0x3']]
2021-12-07 11:06:05,246 - stages.py[INFO]: Applying network configuration from ds bringup=False: {'version': 2, 'ethernets': {'eth0': {'dhcp4': True, 'dhcp4-overrides': {'route-metric': 100}, 'dhcp6': False, 'match': {'macaddress': '60:45:bd:87:66:71', 'driver': 'hv_netvsc'}, 'set-name': 'eth0'}}}
2021-12-07 11:06:05,247 - util.py[DEBUG]: Writing to /run/cloud-init/sem/apply_network_config.once - wb: [644] 24 bytes
2021-12-07 11:06:05,248 - network_state.py[DEBUG]: v2(ethernets) -> v1(physical):
{'type': 'physical', 'name': 'eth0', 'mac_address': '60:45:bd:87:66:71', 'params': {'driver': 'hv_netvsc'}, 'match': {'macaddress': '60:45:bd:87:66:71', 'driver': 'hv_netvsc'}, 'subnets': [{'type': 'dhcp4', 'metric': 100}]}
2021-12-07 11:06:05,250 - network_state.py[DEBUG]: v2_common: handling config:
{'eth0': {'dhcp4': True, 'dhcp4-overrides': {'route-metric': 100}, 'dhcp6': False, 'match': {'macaddress': '60:45:bd:87:66:71', 'driver': 'hv_netvsc'}, 'set-name': 'eth0'}}
2021-12-07 11:06:05,251 - __init__.py[DEBUG]: Selected renderer 'netplan' from priority list: None
2021-12-07 11:06:05,252 - netplan.py[DEBUG]: V2 to V2 passthrough
2021-12-07 11:06:05,253 - util.py[DEBUG]: Writing to /etc/netplan/50-cloud-init.yaml - wb: [644] 603 bytes
2021-12-07 11:06:05,253 - subp.py[DEBUG]: Running command ['netplan', 'generate'] with allowed return codes [0] (shell=False, capture=True)
2021-12-07 11:06:05,396 - subp.py[DEBUG]: Running command ['udevadm', 'test-builtin', 'net_setup_link', '/sys/class/net/eth0'] with allowed return codes [0] (shell=False, capture=True)
2021-12-07 11:06:05,403 - subp.py[DEBUG]: Running command ['udevadm', 'test-builtin', 'net_setup_link', '/sys/class/net/lo'] with allowed return codes [0] (shell=False, capture=True)
2021-12-07 11:06:05,410 - __init__.py[DEBUG]: Not bringing up newly configured network interfaces
2021-12-07 11:06:05,411 - main.py[DEBUG]: [local] Exiting. datasource DataSourceAzure [seed=/dev/sr0] not in local mode.
2021-12-07 11:06:05,411 - atomic_helper.py[DEBUG]: Atomically writing to file /var/lib/cloud/data/status.json (via temporary file /var/lib/cloud/data/tmp1xlouuck) - w: [644] 504 bytes/chars
2021-12-07 11:06:05,412 - util.py[DEBUG]: Reading from /proc/uptime (quiet=False)
2021-12-07 11:06:05,412 - util.py[DEBUG]: Read 11 bytes from /proc/uptime
2021-12-07 11:06:05,412 - util.py[DEBUG]: cloud-init mode 'init' took 3.016 seconds (3.02)
2021-12-07 11:06:05,412 - handlers.py[DEBUG]: HyperVReportingHandler flushing remaining events
2021-12-07 11:06:05,412 - handlers.py[DEBUG]: finish: init-local: SUCCESS: searching for local datasources
2021-12-07 11:06:07,986 - util.py[DEBUG]: Reading from /proc/uptime (quiet=False)
2021-12-07 11:06:07,986 - util.py[DEBUG]: Read 11 bytes from /proc/uptime
2021-12-07 11:06:07,986 - util.py[DEBUG]: Reading from /proc/uptime (quiet=False)
2021-12-07 11:06:07,986 - util.py[DEBUG]: Read 11 bytes from /proc/uptime
2021-12-07 11:06:07,987 - util.py[DEBUG]: Cloud-init v. 21.4-0ubuntu1~18.04.1 running 'init' at Tue, 07 Dec 2021 11:06:07 +0000. Up 17.19 seconds.
2021-12-07 11:06:07,987 - main.py[DEBUG]: No kernel command line url found.
2021-12-07 11:06:07,987 - main.py[DEBUG]: Closing stdin.
2021-12-07 11:06:07,989 - util.py[DEBUG]: Writing to /var/log/cloud-init.log - ab: [644] 0 bytes
2021-12-07 11:06:07,992 - util.py[DEBUG]: Changing the ownership of /var/log/cloud-init.log to 102:4
2021-12-07 11:06:07,993 - subp.py[DEBUG]: Running command ['ip', 'addr', 'show'] with allowed return codes [0] (shell=False, capture=True)
2021-12-07 11:06:08,001 - subp.py[DEBUG]: Running command ['ip', '-o', 'route', 'list'] with allowed return codes [0] (shell=False, capture=True)
2021-12-07 11:06:08,005 - subp.py[DEBUG]: Running command ['ip', '--oneline', '-6', 'route', 'list', 'table', 'all'] with allowed return codes [0, 1] (shell=False, capture=True)
2021-12-07 11:06:08,009 - main.py[DEBUG]: Checking to see if files that we need already exist from a previous run that would allow us to stop early.
2021-12-07 11:06:08,010 - main.py[DEBUG]: Execution continuing, no previous run detected that would allow us to stop early.
2021-12-07 11:06:08,010 - handlers.py[DEBUG]: start: init-network/check-cache: attempting to read from cache [trust]
2021-12-07 11:06:08,010 - util.py[DEBUG]: Reading from /var/lib/cloud/instance/obj.pkl (quiet=False)
2021-12-07 11:06:08,011 - util.py[DEBUG]: Read 10757 bytes from /var/lib/cloud/instance/obj.pkl
2021-12-07 11:06:08,034 - util.py[DEBUG]: Reading from /run/cloud-init/.instance-id (quiet=False)
2021-12-07 11:06:08,035 - util.py[DEBUG]: Read 37 bytes from /run/cloud-init/.instance-id
2021-12-07 11:06:08,035 - stages.py[DEBUG]: restored from cache with run check: DataSourceAzure [seed=/dev/sr0]
2021-12-07 11:06:08,035 - handlers.py[DEBUG]: finish: init-network/check-cache: SUCCESS: restored from cache with run check: DataSourceAzure [seed=/dev/sr0]
2021-12-07 11:06:08,035 - util.py[DEBUG]: Reading from /etc/cloud/cloud.cfg (quiet=False)
2021-12-07 11:06:08,036 - util.py[DEBUG]: Read 3747 bytes from /etc/cloud/cloud.cfg
2021-12-07 11:06:08,036 - util.py[DEBUG]: Attempting to load yaml from string of length 3747 with allowed root types (<class 'dict'>,)
2021-12-07 11:06:08,049 - util.py[DEBUG]: Reading from /etc/cloud/cloud.cfg.d/90_dpkg.cfg (quiet=False)
2021-12-07 11:06:08,049 - util.py[DEBUG]: Read 82 bytes from /etc/cloud/cloud.cfg.d/90_dpkg.cfg
2021-12-07 11:06:08,049 - util.py[DEBUG]: Attempting to load yaml from string of length 82 with allowed root types (<class 'dict'>,)
2021-12-07 11:06:08,050 - util.py[DEBUG]: Reading from /etc/cloud/cloud.cfg.d/90-azure.cfg (quiet=False)
2021-12-07 11:06:08,050 - util.py[DEBUG]: Read 535 bytes from /etc/cloud/cloud.cfg.d/90-azure.cfg
2021-12-07 11:06:08,050 - util.py[DEBUG]: Attempting to load yaml from string of length 535 with allowed root types (<class 'dict'>,)
2021-12-07 11:06:08,052 - util.py[DEBUG]: Reading from /etc/cloud/cloud.cfg.d/10-azure-kvp.cfg (quiet=False)
2021-12-07 11:06:08,052 - util.py[DEBUG]: Read 143 bytes from /etc/cloud/cloud.cfg.d/10-azure-kvp.cfg
2021-12-07 11:06:08,052 - util.py[DEBUG]: Attempting to load yaml from string of length 143 with allowed root types (<class 'dict'>,)
2021-12-07 11:06:08,053 - util.py[DEBUG]: Reading from /etc/cloud/cloud.cfg.d/05_logging.cfg (quiet=False)
2021-12-07 11:06:08,053 - util.py[DEBUG]: Read 2070 bytes from /etc/cloud/cloud.cfg.d/05_logging.cfg
2021-12-07 11:06:08,053 - util.py[DEBUG]: Attempting to load yaml from string of length 2070 with allowed root types (<class 'dict'>,)
2021-12-07 11:06:08,057 - util.py[DEBUG]: Reading from /run/cloud-init/cloud.cfg (quiet=False)
2021-12-07 11:06:08,058 - util.py[DEBUG]: Read 33 bytes from /run/cloud-init/cloud.cfg
2021-12-07 11:06:08,058 - util.py[DEBUG]: Attempting to load yaml from string of length 33 with allowed root types (<class 'dict'>,)
2021-12-07 11:06:08,058 - util.py[DEBUG]: Attempting to load yaml from string of length 0 with allowed root types (<class 'dict'>,)
2021-12-07 11:06:08,058 - util.py[DEBUG]: loaded blob returned None, returning default.
2021-12-07 11:06:08,059 - util.py[DEBUG]: Attempting to remove /var/lib/cloud/instance
2021-12-07 11:06:08,059 - util.py[DEBUG]: Creating symbolic link from '/var/lib/cloud/instance' => '/var/lib/cloud/instances/9d5276fc-2736-a348-9ee7-95af558790ea'
2021-12-07 11:06:08,060 - util.py[DEBUG]: Reading from /var/lib/cloud/instances/9d5276fc-2736-a348-9ee7-95af558790ea/datasource (quiet=False)
2021-12-07 11:06:08,060 - util.py[DEBUG]: Read 49 bytes from /var/lib/cloud/instances/9d5276fc-2736-a348-9ee7-95af558790ea/datasource
2021-12-07 11:06:08,060 - util.py[DEBUG]: Writing to /var/lib/cloud/instances/9d5276fc-2736-a348-9ee7-95af558790ea/datasource - wb: [644] 49 bytes
2021-12-07 11:06:08,060 - util.py[DEBUG]: Writing to /var/lib/cloud/data/previous-datasource - wb: [644] 49 bytes
2021-12-07 11:06:08,061 - util.py[DEBUG]: Reading from /var/lib/cloud/data/instance-id (quiet=False)
2021-12-07 11:06:08,061 - util.py[DEBUG]: Read 37 bytes from /var/lib/cloud/data/instance-id
2021-12-07 11:06:08,061 - stages.py[DEBUG]: previous iid found to be 9d5276fc-2736-a348-9ee7-95af558790ea
2021-12-07 11:06:08,061 - util.py[DEBUG]: Writing to /var/lib/cloud/data/instance-id - wb: [644] 37 bytes
2021-12-07 11:06:08,062 - util.py[DEBUG]: Writing to /run/cloud-init/.instance-id - wb: [644] 37 bytes
2021-12-07 11:06:08,062 - util.py[DEBUG]: Writing to /var/lib/cloud/data/previous-instance-id - wb: [644] 37 bytes
2021-12-07 11:06:08,063 - util.py[DEBUG]: Writing to /var/lib/cloud/instance/obj.pkl - wb: [400] 10783 bytes
2021-12-07 11:06:08,065 - main.py[DEBUG]: [net] init will now be targeting instance id: 9d5276fc-2736-a348-9ee7-95af558790ea. new=False
2021-12-07 11:06:08,065 - util.py[DEBUG]: Reading from /etc/cloud/cloud.cfg (quiet=False)
2021-12-07 11:06:08,065 - util.py[DEBUG]: Read 3747 bytes from /etc/cloud/cloud.cfg
2021-12-07 11:06:08,066 - util.py[DEBUG]: Attempting to load yaml from string of length 3747 with allowed root types (<class 'dict'>,)
2021-12-07 11:06:08,078 - util.py[DEBUG]: Reading from /etc/cloud/cloud.cfg.d/90_dpkg.cfg (quiet=False)
2021-12-07 11:06:08,078 - util.py[DEBUG]: Read 82 bytes from /etc/cloud/cloud.cfg.d/90_dpkg.cfg
2021-12-07 11:06:08,078 - util.py[DEBUG]: Attempting to load yaml from string of length 82 with allowed root types (<class 'dict'>,)
2021-12-07 11:06:08,079 - util.py[DEBUG]: Reading from /etc/cloud/cloud.cfg.d/90-azure.cfg (quiet=False)
2021-12-07 11:06:08,079 - util.py[DEBUG]: Read 535 bytes from /etc/cloud/cloud.cfg.d/90-azure.cfg
2021-12-07 11:06:08,079 - util.py[DEBUG]: Attempting to load yaml from string of length 535 with allowed root types (<class 'dict'>,)
2021-12-07 11:06:08,081 - util.py[DEBUG]: Reading from /etc/cloud/cloud.cfg.d/10-azure-kvp.cfg (quiet=False)
2021-12-07 11:06:08,082 - util.py[DEBUG]: Read 143 bytes from /etc/cloud/cloud.cfg.d/10-azure-kvp.cfg
2021-12-07 11:06:08,082 - util.py[DEBUG]: Attempting to load yaml from string of length 143 with allowed root types (<class 'dict'>,)
2021-12-07 11:06:08,082 - util.py[DEBUG]: Reading from /etc/cloud/cloud.cfg.d/05_logging.cfg (quiet=False)
2021-12-07 11:06:08,083 - util.py[DEBUG]: Read 2070 bytes from /etc/cloud/cloud.cfg.d/05_logging.cfg
2021-12-07 11:06:08,083 - util.py[DEBUG]: Attempting to load yaml from string of length 2070 with allowed root types (<class 'dict'>,)
2021-12-07 11:06:08,086 - util.py[DEBUG]: Reading from /run/cloud-init/cloud.cfg (quiet=False)
2021-12-07 11:06:08,086 - util.py[DEBUG]: Read 33 bytes from /run/cloud-init/cloud.cfg
2021-12-07 11:06:08,086 - util.py[DEBUG]: Attempting to load yaml from string of length 33 with allowed root types (<class 'dict'>,)
2021-12-07 11:06:08,087 - util.py[DEBUG]: Attempting to load yaml from string of length 0 with allowed root types (<class 'dict'>,)
2021-12-07 11:06:08,087 - util.py[DEBUG]: loaded blob returned None, returning default.
2021-12-07 11:06:08,088 - util.py[DEBUG]: Reading from /sys/class/net/eth0/address (quiet=False)
2021-12-07 11:06:08,088 - util.py[DEBUG]: Read 18 bytes from /sys/class/net/eth0/address
2021-12-07 11:06:08,088 - util.py[DEBUG]: Reading from /sys/class/net/lo/address (quiet=False)
2021-12-07 11:06:08,089 - util.py[DEBUG]: Read 18 bytes from /sys/class/net/lo/address
2021-12-07 11:06:08,089 - handlers.py[DEBUG]: start: azure-ds/parse_network_config: parse_network_config
2021-12-07 11:06:08,089 - handlers.py[DEBUG]: start: azure-ds/_generate_network_config_from_imds_metadata: _generate_network_config_from_imds_metadata
2021-12-07 11:06:08,090 - handlers.py[DEBUG]: finish: azure-ds/_generate_network_config_from_imds_metadata: SUCCESS: _generate_network_config_from_imds_metadata
2021-12-07 11:06:08,090 - handlers.py[DEBUG]: finish: azure-ds/parse_network_config: SUCCESS: parse_network_config
2021-12-07 11:06:08,091 - stages.py[DEBUG]: Allowed events: {<EventScope.NETWORK: 'network'>: {<EventType.BOOT_NEW_INSTANCE: 'boot-new-instance'>, <EventType.BOOT: 'boot'>}}
2021-12-07 11:06:08,091 - stages.py[DEBUG]: Event Denied: scopes=['network'] EventType=boot-legacy
2021-12-07 11:06:08,091 - stages.py[DEBUG]: No network config applied. Neither a new instance nor datasource network update allowed
2021-12-07 11:06:08,091 - stages.py[DEBUG]: applying net config names for {'version': 2, 'ethernets': {'eth0': {'dhcp4': True, 'dhcp4-overrides': {'route-metric': 100}, 'dhcp6': False, 'match': {'macaddress': '60:45:bd:87:66:71', 'driver': 'hv_netvsc'}, 'set-name': 'eth0'}}}
2021-12-07 11:06:08,092 - stages.py[DEBUG]: Using distro class <class 'cloudinit.distros.ubuntu.Distro'>
2021-12-07 11:06:08,092 - util.py[DEBUG]: Reading from /sys/class/net/eth0/device/device (quiet=False)
2021-12-07 11:06:08,093 - util.py[DEBUG]: Read 4 bytes from /sys/class/net/eth0/device/device
2021-12-07 11:06:08,093 - util.py[DEBUG]: Reading from /sys/class/net/eth0/addr_assign_type (quiet=False)
2021-12-07 11:06:08,093 - util.py[DEBUG]: Read 2 bytes from /sys/class/net/eth0/addr_assign_type
2021-12-07 11:06:08,093 - util.py[DEBUG]: Reading from /sys/class/net/eth0/uevent (quiet=False)
2021-12-07 11:06:08,093 - util.py[DEBUG]: Read 25 bytes from /sys/class/net/eth0/uevent
2021-12-07 11:06:08,093 - util.py[DEBUG]: Reading from /sys/class/net/eth0/address (quiet=False)
2021-12-07 11:06:08,093 - util.py[DEBUG]: Read 18 bytes from /sys/class/net/eth0/address
2021-12-07 11:06:08,093 - __init__.py[DEBUG]: ovs-vsctl not in PATH; not detecting Open vSwitch interfaces
2021-12-07 11:06:08,094 - util.py[DEBUG]: Reading from /sys/class/net/eth0/device/device (quiet=False)
2021-12-07 11:06:08,094 - util.py[DEBUG]: Read 4 bytes from /sys/class/net/eth0/device/device
2021-12-07 11:06:08,094 - util.py[DEBUG]: Reading from /sys/class/net/lo/addr_assign_type (quiet=False)
2021-12-07 11:06:08,094 - util.py[DEBUG]: Read 2 bytes from /sys/class/net/lo/addr_assign_type
2021-12-07 11:06:08,094 - util.py[DEBUG]: Reading from /sys/class/net/lo/uevent (quiet=False)
2021-12-07 11:06:08,094 - util.py[DEBUG]: Read 23 bytes from /sys/class/net/lo/uevent
2021-12-07 11:06:08,094 - util.py[DEBUG]: Reading from /sys/class/net/lo/address (quiet=False)
2021-12-07 11:06:08,094 - util.py[DEBUG]: Read 18 bytes from /sys/class/net/lo/address
2021-12-07 11:06:08,094 - util.py[DEBUG]: Reading from /sys/class/net/lo/device/device (quiet=False)
2021-12-07 11:06:08,094 - util.py[DEBUG]: Reading from /sys/class/net/eth0/operstate (quiet=False)
2021-12-07 11:06:08,094 - util.py[DEBUG]: Read 3 bytes from /sys/class/net/eth0/operstate
2021-12-07 11:06:08,094 - util.py[DEBUG]: Reading from /sys/class/net/lo/operstate (quiet=False)
2021-12-07 11:06:08,094 - util.py[DEBUG]: Read 8 bytes from /sys/class/net/lo/operstate
2021-12-07 11:06:08,095 - subp.py[DEBUG]: Running command ['ip', '-6', 'addr', 'show', 'permanent', 'scope', 'global'] with allowed return codes [0] (shell=False, capture=True)
2021-12-07 11:06:08,098 - subp.py[DEBUG]: Running command ['ip', '-4', 'addr', 'show'] with allowed return codes [0] (shell=False, capture=True)
2021-12-07 11:06:08,101 - __init__.py[DEBUG]: Detected interfaces {'eth0': {'downable': False, 'device_id': '0x3', 'driver': 'hv_netvsc', 'mac': '60:45:bd:87:66:71', 'name': 'eth0', 'up': True}, 'lo': {'downable': False, 'device_id': None, 'driver': None, 'mac': '00:00:00:00:00:00', 'name': 'lo', 'up': True}}
2021-12-07 11:06:08,101 - __init__.py[DEBUG]: no work necessary for renaming of [['60:45:bd:87:66:71', 'eth0', 'hv_netvsc', '0x3']]
2021-12-07 11:06:08,102 - handlers.py[DEBUG]: start: init-network/setup-datasource: setting up datasource
2021-12-07 11:06:08,102 - handlers.py[DEBUG]: start: azure-ds/setup: setup
2021-12-07 11:06:08,103 - DataSourceAzure.py[DEBUG]: negotiating for 9d5276fc-2736-a348-9ee7-95af558790ea (new_instance=False)
2021-12-07 11:06:08,103 - handlers.py[DEBUG]: start: azure-ds/_negotiate: _negotiate
2021-12-07 11:06:08,103 - handlers.py[DEBUG]: start: azure-ds/bounce_network_with_azure_hostname: bounce_network_with_azure_hostname
2021-12-07 11:06:08,103 - DataSourceAzure.py[DEBUG]: Hostname in metadata is grafana-vm
2021-12-07 11:06:08,104 - handlers.py[DEBUG]: start: azure-ds/temporary_hostname: temporary_hostname
2021-12-07 11:06:08,104 - handlers.py[DEBUG]: finish: azure-ds/temporary_hostname: SUCCESS: temporary_hostname
2021-12-07 11:06:08,104 - subp.py[DEBUG]: Running command ('hostname',) with allowed return codes [0] (shell=False, capture=True)
2021-12-07 11:06:08,107 - handlers.py[DEBUG]: finish: azure-ds/bounce_network_with_azure_hostname: SUCCESS: bounce_network_with_azure_hostname
2021-12-07 11:06:08,107 - DataSourceAzure.py[DEBUG]: Retrieving public SSH keys
2021-12-07 11:06:08,108 - DataSourceAzure.py[DEBUG]: Attempting to get SSH keys from IMDS
2021-12-07 11:06:08,108 - azure.py[DEBUG]: Retrieved 0 keys from IMDS
2021-12-07 11:06:08,108 - DataSourceAzure.py[DEBUG]: negotiating with fabric via agent command __builtin__
2021-12-07 11:06:08,108 - handlers.py[DEBUG]: start: azure-ds/get_metadata_from_fabric: get_metadata_from_fabric
2021-12-07 11:06:08,108 - azure.py[DEBUG]: WALinuxAgentShim instantiated, fallback_lease_file=/var/lib/dhcp/dhclient.eth0.leases
2021-12-07 11:06:08,108 - handlers.py[DEBUG]: start: azure-ds/register_with_azure_and_fetch_data: register_with_azure_and_fetch_data
2021-12-07 11:06:08,108 - handlers.py[DEBUG]: start: azure-ds/_fetch_goal_state_from_azure: _fetch_goal_state_from_azure
2021-12-07 11:06:08,108 - handlers.py[DEBUG]: start: azure-ds/_get_raw_goal_state_xml_from_azure: _get_raw_goal_state_xml_from_azure
2021-12-07 11:06:08,108 - azure.py[INFO]: Registering with Azure...
2021-12-07 11:06:08,108 - handlers.py[DEBUG]: start: azure-ds/find_endpoint: find_endpoint
2021-12-07 11:06:08,108 - azure.py[DEBUG]: No Azure endpoint from dhcp options. Finding Azure endpoint from networkd...
2021-12-07 11:06:08,109 - handlers.py[DEBUG]: start: azure-ds/_networkd_get_value_from_leases: _networkd_get_value_from_leases
2021-12-07 11:06:08,109 - util.py[DEBUG]: Reading from /run/systemd/netif/leases/2 (quiet=False)
2021-12-07 11:06:08,109 - util.py[DEBUG]: Read 425 bytes from /run/systemd/netif/leases/2
2021-12-07 11:06:08,109 - handlers.py[DEBUG]: finish: azure-ds/_networkd_get_value_from_leases: SUCCESS: _networkd_get_value_from_leases
2021-12-07 11:06:08,109 - azure.py[DEBUG]: Azure endpoint found at 168.63.129.16
2021-12-07 11:06:08,110 - handlers.py[DEBUG]: finish: azure-ds/find_endpoint: SUCCESS: find_endpoint
2021-12-07 11:06:08,110 - handlers.py[DEBUG]: start: azure-ds/goalstate-retrieval: retrieve goalstate
2021-12-07 11:06:08,111 - handlers.py[DEBUG]: start: azure-ds/http_with_retries: http_with_retries
2021-12-07 11:06:08,111 - url_helper.py[DEBUG]: [0/1] open 'http://168.63.129.16/machine/?comp=goalstate' with {'url': 'http://168.63.129.16/machine/?comp=goalstate', 'allow_redirects': True, 'method': 'GET', 'timeout': 5.0, 'headers': {'User-Agent': 'Cloud-Init/21.4-0ubuntu1~18.04.1', 'x-ms-agent-name': 'WALinuxAgent', 'x-ms-version': '2012-11-30'}} configuration
2021-12-07 11:06:08,128 - url_helper.py[DEBUG]: Read from http://168.63.129.16/machine/?comp=goalstate (200, 1877b) after 1 attempts
2021-12-07 11:06:08,128 - azure.py[DEBUG]: Successful HTTP request with Azure endpoint http://168.63.129.16/machine/?comp=goalstate after 1 attempts
2021-12-07 11:06:08,128 - handlers.py[DEBUG]: finish: azure-ds/http_with_retries: SUCCESS: http_with_retries
2021-12-07 11:06:08,129 - handlers.py[DEBUG]: finish: azure-ds/goalstate-retrieval: SUCCESS: retrieve goalstate
2021-12-07 11:06:08,129 - azure.py[DEBUG]: Successfully fetched GoalState XML.
2021-12-07 11:06:08,129 - handlers.py[DEBUG]: finish: azure-ds/_get_raw_goal_state_xml_from_azure: SUCCESS: _get_raw_goal_state_xml_from_azure
2021-12-07 11:06:08,129 - handlers.py[DEBUG]: start: azure-ds/_parse_raw_goal_state_xml: _parse_raw_goal_state_xml
2021-12-07 11:06:08,130 - azure.py[DEBUG]: GoalState XML container id: af7f74f9-31e7-4fd9-8f7a-ec65bf8bd0c6, GoalState XML instance id: 9842286a-3874-477c-b70a-8ae0c7b6aad2._grafana, GoalState XML incarnation: 1
2021-12-07 11:06:08,130 - handlers.py[DEBUG]: finish: azure-ds/_parse_raw_goal_state_xml: SUCCESS: _parse_raw_goal_state_xml
2021-12-07 11:06:08,130 - handlers.py[DEBUG]: finish: azure-ds/_fetch_goal_state_from_azure: SUCCESS: _fetch_goal_state_from_azure
2021-12-07 11:06:08,131 - handlers.py[DEBUG]: start: azure-ds/send_ready_signal: send_ready_signal
2021-12-07 11:06:08,131 - azure.py[DEBUG]: Reporting ready to Azure fabric.
2021-12-07 11:06:08,131 - handlers.py[DEBUG]: start: azure-ds/_post_health_report: _post_health_report
2021-12-07 11:06:08,131 - handlers.py[DEBUG]: start: azure-ds/push_log_to_kvp: push_log_to_kvp
2021-12-07 11:06:08,131 - handlers.py[DEBUG]: start: azure-ds/get_last_log_byte_pushed_to_kvp_index: get_last_log_byte_pushed_to_kvp_index
2021-12-07 11:06:08,132 - handlers.py[DEBUG]: finish: azure-ds/get_last_log_byte_pushed_to_kvp_index: SUCCESS: get_last_log_byte_pushed_to_kvp_index
2021-12-07 11:06:08,132 - azure.py[DEBUG]: Dumping cloud-init.log file to KVP
2021-12-07 11:06:08,132 - azure.py[DEBUG]: Dumping last 53541 bytes of cloud-init.log file to KVP starting from index: 0
2021-12-07 11:06:08,134 - util.py[DEBUG]: Writing to /run/cloud-init/log_pushed_to_kvp_index - wb: [644] 5 bytes
2021-12-07 11:06:08,135 - azure.py[DEBUG]: Dumping dmesg log to KVP
2021-12-07 11:06:08,135 - subp.py[DEBUG]: Running command ['dmesg'] with allowed return codes [0] (shell=False, capture=True)
2021-12-07 11:06:08,143 - handlers.py[DEBUG]: finish: azure-ds/push_log_to_kvp: SUCCESS: push_log_to_kvp
2021-12-07 11:06:08,145 - azure.py[DEBUG]: Sending health report to Azure fabric.
2021-12-07 11:06:08,145 - handlers.py[DEBUG]: start: azure-ds/http_with_retries: http_with_retries
2021-12-07 11:06:08,145 - url_helper.py[DEBUG]: [0/1] open 'http://168.63.129.16/machine?comp=health' with {'url': 'http://168.63.129.16/machine?comp=health', 'allow_redirects': True, 'method': 'POST', 'timeout': 5.0, 'headers': {'User-Agent': 'Cloud-Init/21.4-0ubuntu1~18.04.1', 'x-ms-agent-name': 'WALinuxAgent', 'x-ms-version': '2012-11-30', 'Content-Type': 'text/xml; charset=utf-8'}} configuration
2021-12-07 11:06:08,482 - url_helper.py[DEBUG]: Read from http://168.63.129.16/machine?comp=health (200, 0b) after 1 attempts
2021-12-07 11:06:08,483 - azure.py[DEBUG]: Successful HTTP request with Azure endpoint http://168.63.129.16/machine?comp=health after 1 attempts
2021-12-07 11:06:08,483 - handlers.py[DEBUG]: finish: azure-ds/http_with_retries: SUCCESS: http_with_retries
2021-12-07 11:06:08,483 - azure.py[DEBUG]: Successfully sent health report to Azure fabric
2021-12-07 11:06:08,483 - handlers.py[DEBUG]: finish: azure-ds/_post_health_report: SUCCESS: _post_health_report
2021-12-07 11:06:08,483 - azure.py[INFO]: Reported ready to Azure fabric.
2021-12-07 11:06:08,484 - handlers.py[DEBUG]: finish: azure-ds/send_ready_signal: SUCCESS: send_ready_signal
2021-12-07 11:06:08,484 - handlers.py[DEBUG]: finish: azure-ds/register_with_azure_and_fetch_data: SUCCESS: register_with_azure_and_fetch_data
2021-12-07 11:06:08,484 - handlers.py[DEBUG]: finish: azure-ds/get_metadata_from_fabric: SUCCESS: get_metadata_from_fabric
2021-12-07 11:06:08,484 - util.py[DEBUG]: Attempting to remove /var/lib/cloud/data/reported_ready
2021-12-07 11:06:08,485 - util.py[DEBUG]: Attempting to remove /var/lib/cloud/data/poll_imds
2021-12-07 11:06:08,485 - util.py[DEBUG]: Attempting to remove /var/lib/cloud/data/wait_for_nic_attach
2021-12-07 11:06:08,485 - util.py[DEBUG]: Attempting to remove /var/lib/cloud/data/nic_detached
2021-12-07 11:06:08,485 - handlers.py[DEBUG]: finish: azure-ds/_negotiate: SUCCESS: _negotiate
2021-12-07 11:06:08,485 - DataSourceAzure.py[DEBUG]: negotiating returned {'public-keys': None}
2021-12-07 11:06:08,485 - handlers.py[DEBUG]: finish: azure-ds/setup: SUCCESS: setup
2021-12-07 11:06:08,485 - handlers.py[DEBUG]: finish: init-network/setup-datasource: SUCCESS: setting up datasource
2021-12-07 11:06:08,486 - util.py[DEBUG]: Writing to /var/lib/cloud/instances/9d5276fc-2736-a348-9ee7-95af558790ea/user-data.txt - wb: [600] 0 bytes
2021-12-07 11:06:08,489 - util.py[DEBUG]: Writing to /var/lib/cloud/instances/9d5276fc-2736-a348-9ee7-95af558790ea/user-data.txt.i - wb: [600] 308 bytes
2021-12-07 11:06:08,490 - util.py[DEBUG]: Writing to /var/lib/cloud/instances/9d5276fc-2736-a348-9ee7-95af558790ea/vendor-data.txt - wb: [600] 0 bytes
2021-12-07 11:06:08,491 - util.py[DEBUG]: Writing to /var/lib/cloud/instances/9d5276fc-2736-a348-9ee7-95af558790ea/vendor-data.txt.i - wb: [600] 308 bytes
2021-12-07 11:06:08,491 - util.py[DEBUG]: Writing to /var/lib/cloud/instances/9d5276fc-2736-a348-9ee7-95af558790ea/vendor-data2.txt - wb: [600] 0 bytes
2021-12-07 11:06:08,492 - util.py[DEBUG]: Writing to /var/lib/cloud/instances/9d5276fc-2736-a348-9ee7-95af558790ea/vendor-data2.txt.i - wb: [600] 308 bytes
2021-12-07 11:06:08,494 - util.py[DEBUG]: Reading from /var/lib/cloud/data/set-hostname (quiet=False)
2021-12-07 11:06:08,494 - util.py[DEBUG]: Read 53 bytes from /var/lib/cloud/data/set-hostname
2021-12-07 11:06:08,494 - cc_set_hostname.py[DEBUG]: No hostname changes. Skipping set-hostname
2021-12-07 11:06:08,494 - util.py[DEBUG]: Writing to /var/lib/cloud/instances/9d5276fc-2736-a348-9ee7-95af558790ea/sem/consume_data - wb: [644] 24 bytes
2021-12-07 11:06:08,495 - helpers.py[DEBUG]: Running consume_data using lock (<FileLock using file '/var/lib/cloud/instances/9d5276fc-2736-a348-9ee7-95af558790ea/sem/consume_data'>)
2021-12-07 11:06:08,495 - handlers.py[DEBUG]: start: init-network/consume-user-data: reading and applying user-data
2021-12-07 11:06:08,496 - stages.py[DEBUG]: Added default handler for {'text/cloud-config-jsonp', 'text/cloud-config'} from CloudConfigPartHandler: [['text/cloud-config', 'text/cloud-config-jsonp']]
2021-12-07 11:06:08,496 - stages.py[DEBUG]: Added default handler for {'text/x-shellscript'} from ShellScriptPartHandler: [['text/x-shellscript']]
2021-12-07 11:06:08,496 - stages.py[DEBUG]: Added default handler for {'text/cloud-boothook'} from BootHookPartHandler: [['text/cloud-boothook']]
2021-12-07 11:06:08,496 - stages.py[DEBUG]: Added default handler for {'text/upstart-job'} from UpstartJobPartHandler: [['text/upstart-job']]
2021-12-07 11:06:08,496 - stages.py[DEBUG]: Added default handler for {'text/jinja2'} from JinjaTemplatePartHandler: [['text/jinja2']]
2021-12-07 11:06:08,496 - __init__.py[DEBUG]: Calling handler CloudConfigPartHandler: [['text/cloud-config', 'text/cloud-config-jsonp']] (__begin__, None, 3) with frequency once-per-instance
2021-12-07 11:06:08,497 - __init__.py[DEBUG]: Calling handler ShellScriptPartHandler: [['text/x-shellscript']] (__begin__, None, 2) with frequency once-per-instance
2021-12-07 11:06:08,497 - __init__.py[DEBUG]: Calling handler BootHookPartHandler: [['text/cloud-boothook']] (__begin__, None, 2) with frequency once-per-instance
2021-12-07 11:06:08,497 - __init__.py[DEBUG]: Calling handler UpstartJobPartHandler: [['text/upstart-job']] (__begin__, None, 2) with frequency once-per-instance
2021-12-07 11:06:08,497 - __init__.py[DEBUG]: Calling handler JinjaTemplatePartHandler: [['text/jinja2']] (__begin__, None, 3) with frequency once-per-instance
2021-12-07 11:06:08,497 - __init__.py[DEBUG]: {'MIME-Version': '1.0', 'Content-Type': 'text/x-not-multipart', 'Content-Disposition': 'attachment; filename="part-001"'}
2021-12-07 11:06:08,497 - __init__.py[DEBUG]: Empty payload of type text/x-not-multipart
2021-12-07 11:06:08,497 - __init__.py[DEBUG]: Calling handler CloudConfigPartHandler: [['text/cloud-config', 'text/cloud-config-jsonp']] (__end__, None, 3) with frequency once-per-instance
2021-12-07 11:06:08,497 - util.py[DEBUG]: Writing to /var/lib/cloud/instances/9d5276fc-2736-a348-9ee7-95af558790ea/cloud-config.txt - wb: [600] 0 bytes
2021-12-07 11:06:08,498 - __init__.py[DEBUG]: Calling handler ShellScriptPartHandler: [['text/x-shellscript']] (__end__, None, 2) with frequency once-per-instance
2021-12-07 11:06:08,498 - __init__.py[DEBUG]: Calling handler BootHookPartHandler: [['text/cloud-boothook']] (__end__, None, 2) with frequency once-per-instance
2021-12-07 11:06:08,498 - __init__.py[DEBUG]: Calling handler UpstartJobPartHandler: [['text/upstart-job']] (__end__, None, 2) with frequency once-per-instance
2021-12-07 11:06:08,498 - __init__.py[DEBUG]: Calling handler JinjaTemplatePartHandler: [['text/jinja2']] (__end__, None, 3) with frequency once-per-instance
2021-12-07 11:06:08,498 - handlers.py[DEBUG]: finish: init-network/consume-user-data: SUCCESS: reading and applying user-data
2021-12-07 11:06:08,498 - handlers.py[DEBUG]: start: init-network/consume-vendor-data: reading and applying vendor-data
2021-12-07 11:06:08,498 - stages.py[DEBUG]: no vendordata from datasource
2021-12-07 11:06:08,499 - handlers.py[DEBUG]: finish: init-network/consume-vendor-data: SUCCESS: reading and applying vendor-data
2021-12-07 11:06:08,499 - handlers.py[DEBUG]: start: init-network/consume-vendor-data2: reading and applying vendor-data2
2021-12-07 11:06:08,499 - stages.py[DEBUG]: no vendordata2 from datasource
2021-12-07 11:06:08,499 - handlers.py[DEBUG]: finish: init-network/consume-vendor-data2: SUCCESS: reading and applying vendor-data2
2021-12-07 11:06:08,499 - util.py[DEBUG]: Reading from /etc/cloud/cloud.cfg (quiet=False)
2021-12-07 11:06:08,500 - util.py[DEBUG]: Read 3747 bytes from /etc/cloud/cloud.cfg
2021-12-07 11:06:08,500 - util.py[DEBUG]: Attempting to load yaml from string of length 3747 with allowed root types (<class 'dict'>,)
2021-12-07 11:06:08,521 - util.py[DEBUG]: Reading from /etc/cloud/cloud.cfg.d/90_dpkg.cfg (quiet=False)
2021-12-07 11:06:08,521 - util.py[DEBUG]: Read 82 bytes from /etc/cloud/cloud.cfg.d/90_dpkg.cfg
2021-12-07 11:06:08,521 - util.py[DEBUG]: Attempting to load yaml from string of length 82 with allowed root types (<class 'dict'>,)
2021-12-07 11:06:08,522 - util.py[DEBUG]: Reading from /etc/cloud/cloud.cfg.d/90-azure.cfg (quiet=False)
2021-12-07 11:06:08,522 - util.py[DEBUG]: Read 535 bytes from /etc/cloud/cloud.cfg.d/90-azure.cfg
2021-12-07 11:06:08,522 - util.py[DEBUG]: Attempting to load yaml from string of length 535 with allowed root types (<class 'dict'>,)
2021-12-07 11:06:08,524 - util.py[DEBUG]: Reading from /etc/cloud/cloud.cfg.d/10-azure-kvp.cfg (quiet=False)
2021-12-07 11:06:08,524 - util.py[DEBUG]: Read 143 bytes from /etc/cloud/cloud.cfg.d/10-azure-kvp.cfg
2021-12-07 11:06:08,525 - util.py[DEBUG]: Attempting to load yaml from string of length 143 with allowed root types (<class 'dict'>,)
2021-12-07 11:06:08,525 - util.py[DEBUG]: Reading from /etc/cloud/cloud.cfg.d/05_logging.cfg (quiet=False)
2021-12-07 11:06:08,526 - util.py[DEBUG]: Read 2070 bytes from /etc/cloud/cloud.cfg.d/05_logging.cfg
2021-12-07 11:06:08,526 - util.py[DEBUG]: Attempting to load yaml from string of length 2070 with allowed root types (<class 'dict'>,)
2021-12-07 11:06:08,529 - util.py[DEBUG]: Reading from /run/cloud-init/cloud.cfg (quiet=False)
2021-12-07 11:06:08,529 - util.py[DEBUG]: Read 33 bytes from /run/cloud-init/cloud.cfg
2021-12-07 11:06:08,529 - util.py[DEBUG]: Attempting to load yaml from string of length 33 with allowed root types (<class 'dict'>,)
2021-12-07 11:06:08,530 - util.py[DEBUG]: Attempting to load yaml from string of length 0 with allowed root types (<class 'dict'>,)
2021-12-07 11:06:08,530 - util.py[DEBUG]: loaded blob returned None, returning default.
2021-12-07 11:06:08,530 - util.py[DEBUG]: Reading from /var/lib/cloud/instance/cloud-config.txt (quiet=False)
2021-12-07 11:06:08,530 - util.py[DEBUG]: Read 0 bytes from /var/lib/cloud/instance/cloud-config.txt
2021-12-07 11:06:08,530 - util.py[DEBUG]: Attempting to load yaml from string of length 0 with allowed root types (<class 'dict'>,)
2021-12-07 11:06:08,530 - util.py[DEBUG]: loaded blob returned None, returning default.
2021-12-07 11:06:08,531 - util.py[DEBUG]: Reading from /proc/uptime (quiet=False)
2021-12-07 11:06:08,531 - util.py[DEBUG]: Read 11 bytes from /proc/uptime
2021-12-07 11:06:08,532 - util.py[DEBUG]: Reading from /var/lib/cloud/instance/cloud-config.txt (quiet=False)
2021-12-07 11:06:08,532 - util.py[DEBUG]: Read 0 bytes from /var/lib/cloud/instance/cloud-config.txt
2021-12-07 11:06:08,532 - util.py[DEBUG]: Attempting to load yaml from string of length 0 with allowed root types (<class 'dict'>,)
2021-12-07 11:06:08,532 - util.py[DEBUG]: loaded blob returned None, returning default.
2021-12-07 11:06:08,550 - handlers.py[DEBUG]: start: init-network/activate-datasource: activating datasource
2021-12-07 11:06:08,550 - handlers.py[DEBUG]: start: azure-ds/activate: activate
2021-12-07 11:06:08,551 - handlers.py[DEBUG]: start: azure-ds/address_ephemeral_resize: address_ephemeral_resize
2021-12-07 11:06:08,551 - azure.py[DEBUG]: Ephemeral resource disk '/dev/disk/cloud/azure_resource' exists.
2021-12-07 11:06:08,551 - handlers.py[DEBUG]: start: azure-ds/can_dev_be_reformatted: can_dev_be_reformatted
2021-12-07 11:06:08,551 - DataSourceAzure.py[DEBUG]: Resolving realpath of /dev/disk/cloud/azure_resource -> /dev/sdb
2021-12-07 11:06:08,551 - handlers.py[DEBUG]: start: azure-ds/_has_ntfs_filesystem: _has_ntfs_filesystem
2021-12-07 11:06:08,551 - subp.py[DEBUG]: Running command ['blkid', '-tTYPE=ntfs', '-c', '/dev/null', '-odevice'] with allowed return codes [0, 2] (shell=False, capture=True)
2021-12-07 11:06:08,647 - DataSourceAzure.py[DEBUG]: ntfs_devices found = ['/dev/sdb1']
2021-12-07 11:06:08,647 - handlers.py[DEBUG]: finish: azure-ds/_has_ntfs_filesystem: SUCCESS: _has_ntfs_filesystem
2021-12-07 11:06:08,647 - handlers.py[DEBUG]: start: azure-ds/mount-ntfs-and-count: mount-ntfs-and-count
2021-12-07 11:06:08,648 - util.py[DEBUG]: Reading from /proc/mounts (quiet=False)
2021-12-07 11:06:08,648 - util.py[DEBUG]: Read 2296 bytes from /proc/mounts
2021-12-07 11:06:08,648 - util.py[DEBUG]: Fetched {'sysfs': {'fstype': 'sysfs', 'mountpoint': '/sys', 'opts': 'rw,nosuid,nodev,noexec,relatime'}, 'proc': {'fstype': 'proc', 'mountpoint': '/proc', 'opts': 'rw,nosuid,nodev,noexec,relatime'}, 'udev': {'fstype': 'devtmpfs', 'mountpoint': '/dev', 'opts': 'rw,nosuid,relatime,size=1738628k,nr_inodes=434657,mode=755'}, 'devpts': {'fstype': 'devpts', 'mountpoint': '/dev/pts', 'opts': 'rw,nosuid,noexec,relatime,gid=5,mode=620,ptmxmode=000'}, 'tmpfs': {'fstype': 'tmpfs', 'mountpoint': '/sys/fs/cgroup', 'opts': 'ro,nosuid,nodev,noexec,mode=755'}, '/dev/sda1': {'fstype': 'ext4', 'mountpoint': '/', 'opts': 'rw,relatime,discard'}, 'securityfs': {'fstype': 'securityfs', 'mountpoint': '/sys/kernel/security', 'opts': 'rw,nosuid,nodev,noexec,relatime'}, 'cgroup': {'fstype': 'cgroup', 'mountpoint': '/sys/fs/cgroup/perf_event', 'opts': 'rw,nosuid,nodev,noexec,relatime,perf_event'}, 'pstore': {'fstype': 'pstore', 'mountpoint': '/sys/fs/pstore', 'opts': 'rw,nosuid,nodev,noexec,relatime'}, 'systemd-1': {'fstype': 'autofs', 'mountpoint': '/proc/sys/fs/binfmt_misc', 'opts': 'rw,relatime,fd=33,pgrp=1,timeout=0,minproto=5,maxproto=5,direct,pipe_ino=13504'}, 'hugetlbfs': {'fstype': 'hugetlbfs', 'mountpoint': '/dev/hugepages', 'opts': 'rw,relatime,pagesize=2M'}, 'debugfs': {'fstype': 'debugfs', 'mountpoint': '/sys/kernel/debug', 'opts': 'rw,relatime'}, 'mqueue': {'fstype': 'mqueue', 'mountpoint': '/dev/mqueue', 'opts': 'rw,relatime'}, 'configfs': {'fstype': 'configfs', 'mountpoint': '/sys/kernel/config', 'opts': 'rw,relatime'}, 'fusectl': {'fstype': 'fusectl', 'mountpoint': '/sys/fs/fuse/connections', 'opts': 'rw,relatime'}, '/dev/sda15': {'fstype': 'vfat', 'mountpoint': '/boot/efi', 'opts': 'rw,relatime,fmask=0077,dmask=0077,codepage=437,iocharset=iso8859-1,shortname=mixed,errors=remount-ro'}} mounts from proc
2021-12-07 11:06:08,648 - subp.py[DEBUG]: Running command ['mount', '-o', 'ro', '-t', 'ntfs', '/dev/sdb1', '/run/cloud-init/tmp/tmpbphhkgej'] with allowed return codes [0] (shell=False, capture=True)
2021-12-07 11:06:08,765 - handlers.py[DEBUG]: start: azure-ds/count_files: count_files
2021-12-07 11:06:08,768 - handlers.py[DEBUG]: finish: azure-ds/count_files: SUCCESS: count_files
2021-12-07 11:06:08,769 - subp.py[DEBUG]: Running command ['umount', '/run/cloud-init/tmp/tmpbphhkgej'] with allowed return codes [0] (shell=False, capture=True)
2021-12-07 11:06:08,786 - handlers.py[DEBUG]: finish: azure-ds/mount-ntfs-and-count: SUCCESS: mount-ntfs-and-count
2021-12-07 11:06:08,786 - handlers.py[DEBUG]: finish: azure-ds/can_dev_be_reformatted: SUCCESS: can_dev_be_reformatted
2021-12-07 11:06:08,786 - DataSourceAzure.py[DEBUG]: reformattable=True: partition 1 (/dev/sdb1) on device /dev/disk/cloud/azure_resource was ntfs formatted and had no important files. Safe for reformatting.
2021-12-07 11:06:08,786 - DataSourceAzure.py[DEBUG]: Marker "/var/lib/cloud/instance/sem/config_disk_setup" for module "disk_setup" did not exist.
2021-12-07 11:06:08,786 - DataSourceAzure.py[DEBUG]: Marker "/var/lib/cloud/instance/sem/config_mounts" for module "mounts" did not exist.
2021-12-07 11:06:08,787 - handlers.py[DEBUG]: finish: azure-ds/address_ephemeral_resize: SUCCESS: address_ephemeral_resize
2021-12-07 11:06:08,787 - handlers.py[DEBUG]: start: azure-ds/push_log_to_kvp: push_log_to_kvp
2021-12-07 11:06:08,787 - handlers.py[DEBUG]: start: azure-ds/get_last_log_byte_pushed_to_kvp_index: get_last_log_byte_pushed_to_kvp_index
2021-12-07 11:06:08,787 - handlers.py[DEBUG]: finish: azure-ds/get_last_log_byte_pushed_to_kvp_index: SUCCESS: get_last_log_byte_pushed_to_kvp_index
2021-12-07 11:06:08,787 - azure.py[DEBUG]: Dumping cloud-init.log file to KVP
2021-12-07 11:06:08,787 - azure.py[DEBUG]: Dumping last 16425 bytes of cloud-init.log file to KVP starting from index: 53662
2021-12-07 11:06:08,788 - util.py[DEBUG]: Writing to /run/cloud-init/log_pushed_to_kvp_index - wb: [644] 5 bytes
2021-12-07 11:06:08,788 - azure.py[DEBUG]: Dumping dmesg log to KVP
2021-12-07 11:06:08,789 - subp.py[DEBUG]: Running command ['dmesg'] with allowed return codes [0] (shell=False, capture=True)
2021-12-07 11:06:08,808 - handlers.py[DEBUG]: finish: azure-ds/push_log_to_kvp: SUCCESS: push_log_to_kvp
2021-12-07 11:06:08,814 - handlers.py[DEBUG]: finish: azure-ds/activate: SUCCESS: activate
2021-12-07 11:06:08,815 - util.py[DEBUG]: Writing to /var/lib/cloud/instance/obj.pkl - wb: [400] 13883 bytes
2021-12-07 11:06:08,816 - handlers.py[DEBUG]: finish: init-network/activate-datasource: SUCCESS: activating datasource
2021-12-07 11:06:08,816 - main.py[DEBUG]: no di_report found in config.
2021-12-07 11:06:08,874 - stages.py[DEBUG]: Using distro class <class 'cloudinit.distros.ubuntu.Distro'>
2021-12-07 11:06:08,875 - stages.py[DEBUG]: Running module migrator (<module 'cloudinit.config.cc_migrator' from '/usr/lib/python3/dist-packages/cloudinit/config/cc_migrator.py'>) with frequency always
2021-12-07 11:06:08,875 - handlers.py[DEBUG]: start: init-network/config-migrator: running config-migrator with frequency always
2021-12-07 11:06:08,875 - helpers.py[DEBUG]: Running config-migrator using lock (<cloudinit.helpers.DummyLock object at 0x7f2d8a642588>)
2021-12-07 11:06:08,875 - cc_migrator.py[DEBUG]: Migrated 0 semaphore files to there canonicalized names
2021-12-07 11:06:08,876 - handlers.py[DEBUG]: finish: init-network/config-migrator: SUCCESS: config-migrator ran successfully
2021-12-07 11:06:08,876 - stages.py[DEBUG]: Running module seed_random (<module 'cloudinit.config.cc_seed_random' from '/usr/lib/python3/dist-packages/cloudinit/config/cc_seed_random.py'>) with frequency once-per-instance
2021-12-07 11:06:08,877 - handlers.py[DEBUG]: start: init-network/config-seed_random: running config-seed_random with frequency once-per-instance
2021-12-07 11:06:08,878 - util.py[DEBUG]: Writing to /var/lib/cloud/instances/9d5276fc-2736-a348-9ee7-95af558790ea/sem/config_seed_random - wb: [644] 24 bytes
2021-12-07 11:06:08,878 - helpers.py[DEBUG]: Running config-seed_random using lock (<FileLock using file '/var/lib/cloud/instances/9d5276fc-2736-a348-9ee7-95af558790ea/sem/config_seed_random'>)
2021-12-07 11:06:08,878 - cc_seed_random.py[DEBUG]: seed_random: adding 136 bytes of random seed entropy to /dev/urandom
2021-12-07 11:06:08,878 - util.py[DEBUG]: Writing to /dev/urandom - ab: [None] 136 bytes
2021-12-07 11:06:08,879 - cc_seed_random.py[DEBUG]: no command provided
2021-12-07 11:06:08,879 - handlers.py[DEBUG]: finish: init-network/config-seed_random: SUCCESS: config-seed_random ran successfully
2021-12-07 11:06:08,882 - stages.py[DEBUG]: Running module bootcmd (<module 'cloudinit.config.cc_bootcmd' from '/usr/lib/python3/dist-packages/cloudinit/config/cc_bootcmd.py'>) with frequency always
2021-12-07 11:06:08,882 - handlers.py[DEBUG]: start: init-network/config-bootcmd: running config-bootcmd with frequency always
2021-12-07 11:06:08,883 - helpers.py[DEBUG]: Running config-bootcmd using lock (<cloudinit.helpers.DummyLock object at 0x7f2d8a642ba8>)
2021-12-07 11:06:08,883 - cc_bootcmd.py[DEBUG]: Skipping module named bootcmd, no 'bootcmd' key in configuration
2021-12-07 11:06:08,883 - handlers.py[DEBUG]: finish: init-network/config-bootcmd: SUCCESS: config-bootcmd ran successfully
2021-12-07 11:06:08,883 - stages.py[DEBUG]: Running module write-files (<module 'cloudinit.config.cc_write_files' from '/usr/lib/python3/dist-packages/cloudinit/config/cc_write_files.py'>) with frequency once-per-instance
2021-12-07 11:06:08,883 - handlers.py[DEBUG]: start: init-network/config-write-files: running config-write-files with frequency once-per-instance
2021-12-07 11:06:08,884 - util.py[DEBUG]: Writing to /var/lib/cloud/instances/9d5276fc-2736-a348-9ee7-95af558790ea/sem/config_write_files - wb: [644] 24 bytes
2021-12-07 11:06:08,884 - helpers.py[DEBUG]: Running config-write-files using lock (<FileLock using file '/var/lib/cloud/instances/9d5276fc-2736-a348-9ee7-95af558790ea/sem/config_write_files'>)
2021-12-07 11:06:08,916 - cc_write_files.py[DEBUG]: Skipping module named write-files, no/empty 'write_files' key in configuration
2021-12-07 11:06:08,916 - handlers.py[DEBUG]: finish: init-network/config-write-files: SUCCESS: config-write-files ran successfully
2021-12-07 11:06:08,916 - stages.py[DEBUG]: Running module growpart (<module 'cloudinit.config.cc_growpart' from '/usr/lib/python3/dist-packages/cloudinit/config/cc_growpart.py'>) with frequency always
2021-12-07 11:06:08,917 - handlers.py[DEBUG]: start: init-network/config-growpart: running config-growpart with frequency always
2021-12-07 11:06:08,917 - helpers.py[DEBUG]: Running config-growpart using lock (<cloudinit.helpers.DummyLock object at 0x7f2d89d7a7f0>)
2021-12-07 11:06:08,917 - cc_growpart.py[DEBUG]: No 'growpart' entry in cfg.  Using default: {'mode': 'auto', 'devices': ['/'], 'ignore_growroot_disabled': False}
2021-12-07 11:06:08,917 - subp.py[DEBUG]: Running command ['growpart', '--help'] with allowed return codes [0] (shell=False, capture=True)
2021-12-07 11:06:08,929 - util.py[DEBUG]: Reading from /proc/809/mountinfo (quiet=False)
2021-12-07 11:06:08,929 - util.py[DEBUG]: Read 3025 bytes from /proc/809/mountinfo
2021-12-07 11:06:08,937 - util.py[DEBUG]: Reading from /sys/class/block/sda1/partition (quiet=False)
2021-12-07 11:06:08,937 - util.py[DEBUG]: Read 2 bytes from /sys/class/block/sda1/partition
2021-12-07 11:06:08,938 - util.py[DEBUG]: Reading from /sys/devices/LNXSYSTM:00/LNXSYBUS:00/PNP0A03:00/device:07/VMBUS:01/00000000-0000-8899-0000-000000000000/host0/target0:0:0/0:0:0:0/block/sda/dev (quiet=False)
2021-12-07 11:06:08,938 - util.py[DEBUG]: Read 4 bytes from /sys/devices/LNXSYSTM:00/LNXSYBUS:00/PNP0A03:00/device:07/VMBUS:01/00000000-0000-8899-0000-000000000000/host0/target0:0:0/0:0:0:0/block/sda/dev
2021-12-07 11:06:08,938 - subp.py[DEBUG]: Running command ['growpart', '--dry-run', '/dev/sda', '1'] with allowed return codes [0] (shell=False, capture=True)
2021-12-07 11:06:09,160 - subp.py[DEBUG]: Running command ['growpart', '/dev/sda', '1'] with allowed return codes [0] (shell=False, capture=True)
2021-12-07 11:06:09,767 - util.py[DEBUG]: resize_devices took 0.839 seconds
2021-12-07 11:06:09,768 - cc_growpart.py[INFO]: '/' resized: changed (/dev/sda, 1) from 2244984320 to 32096894464
2021-12-07 11:06:09,768 - handlers.py[DEBUG]: finish: init-network/config-growpart: SUCCESS: config-growpart ran successfully
2021-12-07 11:06:09,768 - stages.py[DEBUG]: Running module resizefs (<module 'cloudinit.config.cc_resizefs' from '/usr/lib/python3/dist-packages/cloudinit/config/cc_resizefs.py'>) with frequency always
2021-12-07 11:06:09,769 - handlers.py[DEBUG]: start: init-network/config-resizefs: running config-resizefs with frequency always
2021-12-07 11:06:09,769 - helpers.py[DEBUG]: Running config-resizefs using lock (<cloudinit.helpers.DummyLock object at 0x7f2d89d7a9e8>)
2021-12-07 11:06:09,777 - util.py[DEBUG]: Reading from /proc/809/mountinfo (quiet=False)
2021-12-07 11:06:09,778 - util.py[DEBUG]: Read 3025 bytes from /proc/809/mountinfo
2021-12-07 11:06:09,778 - cc_resizefs.py[DEBUG]: resize_info: dev=/dev/sda1 mnt_point=/ path=/
2021-12-07 11:06:09,778 - cc_resizefs.py[DEBUG]: Resizing / (ext4) using resize2fs /dev/sda1
2021-12-07 11:06:09,778 - subp.py[DEBUG]: Running command ('resize2fs', '/dev/sda1') with allowed return codes [0] (shell=False, capture=True)
2021-12-07 11:06:11,116 - util.py[DEBUG]: Resizing took 1.338 seconds
2021-12-07 11:06:11,116 - cc_resizefs.py[DEBUG]: Resized root filesystem (type=ext4, val=True)
2021-12-07 11:06:11,116 - handlers.py[DEBUG]: finish: init-network/config-resizefs: SUCCESS: config-resizefs ran successfully
2021-12-07 11:06:11,117 - stages.py[DEBUG]: Running module disk_setup (<module 'cloudinit.config.cc_disk_setup' from '/usr/lib/python3/dist-packages/cloudinit/config/cc_disk_setup.py'>) with frequency once-per-instance
2021-12-07 11:06:11,117 - handlers.py[DEBUG]: start: init-network/config-disk_setup: running config-disk_setup with frequency once-per-instance
2021-12-07 11:06:11,117 - util.py[DEBUG]: Writing to /var/lib/cloud/instances/9d5276fc-2736-a348-9ee7-95af558790ea/sem/config_disk_setup - wb: [644] 23 bytes
2021-12-07 11:06:11,118 - helpers.py[DEBUG]: Running config-disk_setup using lock (<FileLock using file '/var/lib/cloud/instances/9d5276fc-2736-a348-9ee7-95af558790ea/sem/config_disk_setup'>)
2021-12-07 11:06:11,118 - cc_disk_setup.py[DEBUG]: updated disk_setup device entry 'ephemeral0' to '/dev/disk/cloud/azure_resource'
2021-12-07 11:06:11,118 - cc_disk_setup.py[DEBUG]: Partitioning disks: {'/dev/disk/cloud/azure_resource': {'table_type': 'gpt', 'layout': [100], 'overwrite': True, '_origname': 'ephemeral0'}}
2021-12-07 11:06:11,119 - cc_disk_setup.py[DEBUG]: Creating new partition table/disk
2021-12-07 11:06:11,119 - subp.py[DEBUG]: Running command ['udevadm', 'settle'] with allowed return codes [0] (shell=False, capture=True)
2021-12-07 11:06:11,138 - cc_disk_setup.py[DEBUG]: Checking values for /dev/sdb definition
2021-12-07 11:06:11,139 - cc_disk_setup.py[DEBUG]: Checking against default devices
2021-12-07 11:06:11,139 - cc_disk_setup.py[DEBUG]: Checking if device /dev/sdb is a valid device
2021-12-07 11:06:11,139 - subp.py[DEBUG]: Running command ['/bin/lsblk', '--pairs', '--output', 'NAME,TYPE,FSTYPE,LABEL', '/dev/sdb', '--nodeps'] with allowed return codes [0] (shell=False, capture=True)
2021-12-07 11:06:11,145 - cc_disk_setup.py[DEBUG]: Checking if device layout matches
2021-12-07 11:06:11,145 - subp.py[DEBUG]: Running command ['/sbin/sgdisk', '-p', '/dev/sdb'] with allowed return codes [0] (shell=False, capture=True)
2021-12-07 11:06:11,334 - cc_disk_setup.py[DEBUG]: called check_partition_gpt_layout(/dev/sdb, [100]), returned: ['07']
2021-12-07 11:06:11,334 - cc_disk_setup.py[DEBUG]: Layout types=[None]. Found types=['07']
2021-12-07 11:06:11,334 - cc_disk_setup.py[DEBUG]: Device partitioning layout matches
2021-12-07 11:06:11,334 - util.py[DEBUG]: Creating partition on /dev/disk/cloud/azure_resource took 0.215 seconds
2021-12-07 11:06:11,334 - cc_disk_setup.py[DEBUG]: setting up filesystems: [{'filesystem': 'ext4', 'device': 'ephemeral0.1'}]
2021-12-07 11:06:11,334 - cc_disk_setup.py[DEBUG]: ephemeral0.1 is mapped to disk=/dev/disk/cloud/azure_resource part=1
2021-12-07 11:06:11,334 - cc_disk_setup.py[DEBUG]: Creating new filesystem.
2021-12-07 11:06:11,334 - subp.py[DEBUG]: Running command ['udevadm', 'settle'] with allowed return codes [0] (shell=False, capture=True)
2021-12-07 11:06:11,394 - cc_disk_setup.py[DEBUG]: Checking /dev/sdb against default devices
2021-12-07 11:06:11,395 - cc_disk_setup.py[DEBUG]: Manual request of partition 1 for /dev/sdb1
2021-12-07 11:06:11,395 - cc_disk_setup.py[DEBUG]: Checking device /dev/sdb1
2021-12-07 11:06:11,395 - subp.py[DEBUG]: Running command ['/sbin/blkid', '-c', '/dev/null', '/dev/sdb1'] with allowed return codes [0, 2] (shell=False, capture=True)
2021-12-07 11:06:11,406 - cc_disk_setup.py[DEBUG]: Device '/dev/sdb1' has check_label='Temporary Storage' check_fstype=ntfs
2021-12-07 11:06:11,406 - cc_disk_setup.py[DEBUG]: Device /dev/sdb1 is cleared for formating
2021-12-07 11:06:11,407 - cc_disk_setup.py[DEBUG]: File system type 'ext4' with label 'None' will be created on /dev/sdb1
2021-12-07 11:06:11,407 - subp.py[DEBUG]: Running command ['/bin/lsblk', '--pairs', '--output', 'NAME,TYPE,FSTYPE,LABEL', '/dev/sdb1', '--nodeps'] with allowed return codes [0] (shell=False, capture=True)
2021-12-07 11:06:11,412 - cc_disk_setup.py[DEBUG]: Creating file system None on /dev/sdb1
2021-12-07 11:06:11,412 - cc_disk_setup.py[DEBUG]:      Using cmd: ['/sbin/mkfs.ext4', '/dev/sdb1']
2021-12-07 11:06:11,413 - subp.py[DEBUG]: Running command ['/sbin/mkfs.ext4', '/dev/sdb1'] with allowed return codes [0] (shell=False, capture=True)
2021-12-07 11:06:11,755 - util.py[DEBUG]: Creating fs for /dev/disk/cloud/azure_resource took 0.420 seconds
2021-12-07 11:06:11,755 - handlers.py[DEBUG]: finish: init-network/config-disk_setup: SUCCESS: config-disk_setup ran successfully
2021-12-07 11:06:11,755 - stages.py[DEBUG]: Running module mounts (<module 'cloudinit.config.cc_mounts' from '/usr/lib/python3/dist-packages/cloudinit/config/cc_mounts.py'>) with frequency once-per-instance
2021-12-07 11:06:11,756 - handlers.py[DEBUG]: start: init-network/config-mounts: running config-mounts with frequency once-per-instance
2021-12-07 11:06:11,756 - util.py[DEBUG]: Writing to /var/lib/cloud/instances/9d5276fc-2736-a348-9ee7-95af558790ea/sem/config_mounts - wb: [644] 24 bytes
2021-12-07 11:06:11,757 - helpers.py[DEBUG]: Running config-mounts using lock (<FileLock using file '/var/lib/cloud/instances/9d5276fc-2736-a348-9ee7-95af558790ea/sem/config_mounts'>)
2021-12-07 11:06:11,757 - cc_mounts.py[DEBUG]: mounts configuration is []
2021-12-07 11:06:11,757 - util.py[DEBUG]: Reading from /etc/fstab (quiet=False)
2021-12-07 11:06:11,757 - util.py[DEBUG]: Read 193 bytes from /etc/fstab
2021-12-07 11:06:11,757 - cc_mounts.py[DEBUG]: Attempting to determine the real name of ephemeral0
2021-12-07 11:06:11,757 - cc_mounts.py[DEBUG]: Mapped metadata name ephemeral0 to /dev/disk/cloud/azure_resource
2021-12-07 11:06:11,759 - cc_mounts.py[DEBUG]: changed default device ephemeral0 => /dev/disk/cloud/azure_resource-part1
2021-12-07 11:06:11,759 - cc_mounts.py[DEBUG]: Attempting to determine the real name of swap
2021-12-07 11:06:11,759 - cc_mounts.py[DEBUG]: changed default device swap => None
2021-12-07 11:06:11,759 - cc_mounts.py[DEBUG]: Ignoring nonexistent default named mount swap
2021-12-07 11:06:11,759 - cc_mounts.py[DEBUG]: no need to setup swap
2021-12-07 11:06:11,759 - util.py[DEBUG]: Reading from /proc/mounts (quiet=False)
2021-12-07 11:06:11,759 - util.py[DEBUG]: Read 2296 bytes from /proc/mounts
2021-12-07 11:06:11,759 - util.py[DEBUG]: Fetched {'sysfs': {'fstype': 'sysfs', 'mountpoint': '/sys', 'opts': 'rw,nosuid,nodev,noexec,relatime'}, 'proc': {'fstype': 'proc', 'mountpoint': '/proc', 'opts': 'rw,nosuid,nodev,noexec,relatime'}, 'udev': {'fstype': 'devtmpfs', 'mountpoint': '/dev', 'opts': 'rw,nosuid,relatime,size=1738628k,nr_inodes=434657,mode=755'}, 'devpts': {'fstype': 'devpts', 'mountpoint': '/dev/pts', 'opts': 'rw,nosuid,noexec,relatime,gid=5,mode=620,ptmxmode=000'}, 'tmpfs': {'fstype': 'tmpfs', 'mountpoint': '/sys/fs/cgroup', 'opts': 'ro,nosuid,nodev,noexec,mode=755'}, '/dev/sda1': {'fstype': 'ext4', 'mountpoint': '/', 'opts': 'rw,relatime,discard'}, 'securityfs': {'fstype': 'securityfs', 'mountpoint': '/sys/kernel/security', 'opts': 'rw,nosuid,nodev,noexec,relatime'}, 'cgroup': {'fstype': 'cgroup', 'mountpoint': '/sys/fs/cgroup/perf_event', 'opts': 'rw,nosuid,nodev,noexec,relatime,perf_event'}, 'pstore': {'fstype': 'pstore', 'mountpoint': '/sys/fs/pstore', 'opts': 'rw,nosuid,nodev,noexec,relatime'}, 'systemd-1': {'fstype': 'autofs', 'mountpoint': '/proc/sys/fs/binfmt_misc', 'opts': 'rw,relatime,fd=33,pgrp=1,timeout=0,minproto=5,maxproto=5,direct,pipe_ino=13504'}, 'hugetlbfs': {'fstype': 'hugetlbfs', 'mountpoint': '/dev/hugepages', 'opts': 'rw,relatime,pagesize=2M'}, 'debugfs': {'fstype': 'debugfs', 'mountpoint': '/sys/kernel/debug', 'opts': 'rw,relatime'}, 'mqueue': {'fstype': 'mqueue', 'mountpoint': '/dev/mqueue', 'opts': 'rw,relatime'}, 'configfs': {'fstype': 'configfs', 'mountpoint': '/sys/kernel/config', 'opts': 'rw,relatime'}, 'fusectl': {'fstype': 'fusectl', 'mountpoint': '/sys/fs/fuse/connections', 'opts': 'rw,relatime'}, '/dev/sda15': {'fstype': 'vfat', 'mountpoint': '/boot/efi', 'opts': 'rw,relatime,fmask=0077,dmask=0077,codepage=437,iocharset=iso8859-1,shortname=mixed,errors=remount-ro'}} mounts from proc
2021-12-07 11:06:11,760 - util.py[DEBUG]: Writing to /etc/fstab - wb: [644] 318 bytes
2021-12-07 11:06:11,760 - cc_mounts.py[DEBUG]: Changes to fstab: ['+ /dev/disk/cloud/azure_resource-part1 /mnt auto defaults,nofail,x-systemd.requires=cloud-init.service,comment=cloudconfig 0 2']
2021-12-07 11:06:11,760 - subp.py[DEBUG]: Running command ['mount', '-a'] with allowed return codes [0] (shell=False, capture=True)
2021-12-07 11:06:11,800 - cc_mounts.py[DEBUG]: Activate mounts: PASS:mount -a
2021-12-07 11:06:11,800 - subp.py[DEBUG]: Running command ['systemctl', 'daemon-reload'] with allowed return codes [0] (shell=False, capture=True)
2021-12-07 11:06:11,963 - cc_mounts.py[DEBUG]: Activate mounts: PASS:systemctl daemon-reload
2021-12-07 11:06:11,964 - handlers.py[DEBUG]: finish: init-network/config-mounts: SUCCESS: config-mounts ran successfully
2021-12-07 11:06:11,964 - stages.py[DEBUG]: Running module set_hostname (<module 'cloudinit.config.cc_set_hostname' from '/usr/lib/python3/dist-packages/cloudinit/config/cc_set_hostname.py'>) with frequency once-per-instance
2021-12-07 11:06:11,964 - handlers.py[DEBUG]: start: init-network/config-set_hostname: running config-set_hostname with frequency once-per-instance
2021-12-07 11:06:11,965 - util.py[DEBUG]: Writing to /var/lib/cloud/instances/9d5276fc-2736-a348-9ee7-95af558790ea/sem/config_set_hostname - wb: [644] 23 bytes
2021-12-07 11:06:11,965 - helpers.py[DEBUG]: Running config-set_hostname using lock (<FileLock using file '/var/lib/cloud/instances/9d5276fc-2736-a348-9ee7-95af558790ea/sem/config_set_hostname'>)
2021-12-07 11:06:11,967 - util.py[DEBUG]: Reading from /var/lib/cloud/data/set-hostname (quiet=False)
2021-12-07 11:06:11,967 - util.py[DEBUG]: Read 53 bytes from /var/lib/cloud/data/set-hostname
2021-12-07 11:06:11,967 - cc_set_hostname.py[DEBUG]: No hostname changes. Skipping set-hostname
2021-12-07 11:06:11,967 - handlers.py[DEBUG]: finish: init-network/config-set_hostname: SUCCESS: config-set_hostname ran successfully
2021-12-07 11:06:11,970 - stages.py[DEBUG]: Running module update_hostname (<module 'cloudinit.config.cc_update_hostname' from '/usr/lib/python3/dist-packages/cloudinit/config/cc_update_hostname.py'>) with frequency always
2021-12-07 11:06:11,970 - handlers.py[DEBUG]: start: init-network/config-update_hostname: running config-update_hostname with frequency always
2021-12-07 11:06:11,971 - helpers.py[DEBUG]: Running config-update_hostname using lock (<cloudinit.helpers.DummyLock object at 0x7f2d89d7af28>)
2021-12-07 11:06:11,971 - cc_update_hostname.py[DEBUG]: Updating hostname to grafana-vm (grafana-vm)
2021-12-07 11:06:11,971 - util.py[DEBUG]: Reading from /etc/hostname (quiet=False)
2021-12-07 11:06:11,971 - util.py[DEBUG]: Read 11 bytes from /etc/hostname
2021-12-07 11:06:11,971 - __init__.py[DEBUG]: Attempting to update hostname to grafana-vm in 1 files
2021-12-07 11:06:11,971 - util.py[DEBUG]: Reading from /var/lib/cloud/data/previous-hostname (quiet=False)
2021-12-07 11:06:11,971 - util.py[DEBUG]: Writing to /var/lib/cloud/data/previous-hostname - wb: [644] 11 bytes
2021-12-07 11:06:11,972 - handlers.py[DEBUG]: finish: init-network/config-update_hostname: SUCCESS: config-update_hostname ran successfully
2021-12-07 11:06:11,972 - stages.py[DEBUG]: Running module update_etc_hosts (<module 'cloudinit.config.cc_update_etc_hosts' from '/usr/lib/python3/dist-packages/cloudinit/config/cc_update_etc_hosts.py'>) with frequency always
2021-12-07 11:06:11,972 - handlers.py[DEBUG]: start: init-network/config-update_etc_hosts: running config-update_etc_hosts with frequency always
2021-12-07 11:06:11,973 - helpers.py[DEBUG]: Running config-update_etc_hosts using lock (<cloudinit.helpers.DummyLock object at 0x7f2d89d7af60>)
2021-12-07 11:06:11,973 - cc_update_etc_hosts.py[DEBUG]: Configuration option 'manage_etc_hosts' is not set, not managing /etc/hosts in module update_etc_hosts
2021-12-07 11:06:11,973 - handlers.py[DEBUG]: finish: init-network/config-update_etc_hosts: SUCCESS: config-update_etc_hosts ran successfully
2021-12-07 11:06:11,973 - stages.py[DEBUG]: Running module ca-certs (<module 'cloudinit.config.cc_ca_certs' from '/usr/lib/python3/dist-packages/cloudinit/config/cc_ca_certs.py'>) with frequency once-per-instance
2021-12-07 11:06:11,974 - handlers.py[DEBUG]: start: init-network/config-ca-certs: running config-ca-certs with frequency once-per-instance
2021-12-07 11:06:11,974 - util.py[DEBUG]: Writing to /var/lib/cloud/instances/9d5276fc-2736-a348-9ee7-95af558790ea/sem/config_ca_certs - wb: [644] 23 bytes
2021-12-07 11:06:11,975 - helpers.py[DEBUG]: Running config-ca-certs using lock (<FileLock using file '/var/lib/cloud/instances/9d5276fc-2736-a348-9ee7-95af558790ea/sem/config_ca_certs'>)
2021-12-07 11:06:11,975 - cc_ca_certs.py[DEBUG]: Skipping module named ca-certs, no 'ca-certs' key in configuration
2021-12-07 11:06:11,975 - handlers.py[DEBUG]: finish: init-network/config-ca-certs: SUCCESS: config-ca-certs ran successfully
2021-12-07 11:06:11,975 - stages.py[DEBUG]: Running module rsyslog (<module 'cloudinit.config.cc_rsyslog' from '/usr/lib/python3/dist-packages/cloudinit/config/cc_rsyslog.py'>) with frequency once-per-instance
2021-12-07 11:06:11,975 - handlers.py[DEBUG]: start: init-network/config-rsyslog: running config-rsyslog with frequency once-per-instance
2021-12-07 11:06:11,976 - util.py[DEBUG]: Writing to /var/lib/cloud/instances/9d5276fc-2736-a348-9ee7-95af558790ea/sem/config_rsyslog - wb: [644] 23 bytes
2021-12-07 11:06:11,976 - helpers.py[DEBUG]: Running config-rsyslog using lock (<FileLock using file '/var/lib/cloud/instances/9d5276fc-2736-a348-9ee7-95af558790ea/sem/config_rsyslog'>)
2021-12-07 11:06:11,976 - cc_rsyslog.py[DEBUG]: Skipping module named rsyslog, no 'rsyslog' key in configuration
2021-12-07 11:06:11,976 - handlers.py[DEBUG]: finish: init-network/config-rsyslog: SUCCESS: config-rsyslog ran successfully
2021-12-07 11:06:11,976 - stages.py[DEBUG]: Running module users-groups (<module 'cloudinit.config.cc_users_groups' from '/usr/lib/python3/dist-packages/cloudinit/config/cc_users_groups.py'>) with frequency once-per-instance
2021-12-07 11:06:11,977 - handlers.py[DEBUG]: start: init-network/config-users-groups: running config-users-groups with frequency once-per-instance
2021-12-07 11:06:11,977 - util.py[DEBUG]: Writing to /var/lib/cloud/instances/9d5276fc-2736-a348-9ee7-95af558790ea/sem/config_users_groups - wb: [644] 24 bytes
2021-12-07 11:06:11,977 - helpers.py[DEBUG]: Running config-users-groups using lock (<FileLock using file '/var/lib/cloud/instances/9d5276fc-2736-a348-9ee7-95af558790ea/sem/config_users_groups'>)
2021-12-07 11:06:11,978 - handlers.py[DEBUG]: start: azure-ds/get_public_ssh_keys: get_public_ssh_keys
2021-12-07 11:06:11,978 - DataSourceAzure.py[DEBUG]: Retrieving public SSH keys
2021-12-07 11:06:11,978 - DataSourceAzure.py[DEBUG]: Attempting to get SSH keys from IMDS
2021-12-07 11:06:11,978 - azure.py[DEBUG]: Retrieved 0 keys from IMDS
2021-12-07 11:06:11,978 - handlers.py[DEBUG]: finish: azure-ds/get_public_ssh_keys: SUCCESS: get_public_ssh_keys
2021-12-07 11:06:11,979 - util.py[DEBUG]: Reading from /etc/os-release (quiet=True)
2021-12-07 11:06:11,979 - util.py[DEBUG]: Read 386 bytes from /etc/os-release
2021-12-07 11:06:11,980 - util.py[DEBUG]: Reading from /etc/system-image/channel.ini (quiet=True)
2021-12-07 11:06:11,980 - util.py[DEBUG]: Read 0 bytes from /etc/system-image/channel.ini
2021-12-07 11:06:11,980 - __init__.py[DEBUG]: Adding user devGrafanaDashboard
2021-12-07 11:06:11,980 - subp.py[DEBUG]: Running hidden command to protect sensitive input/output logstring: ['useradd', 'devGrafanaDashboard', '--comment', 'Ubuntu', '--groups', 'adm,audio,cdrom,dialout,dip,floppy,lxd,netdev,plugdev,sudo,video', '--password', 'REDACTED', '--shell', '/bin/bash', '-m']
2021-12-07 11:06:12,210 - util.py[DEBUG]: Reading from /etc/sudoers (quiet=False)
2021-12-07 11:06:12,211 - util.py[DEBUG]: Read 755 bytes from /etc/sudoers
2021-12-07 11:06:12,212 - util.py[DEBUG]: Writing to /etc/sudoers.d/90-cloud-init-users - wb: [440] 165 bytes
2021-12-07 11:06:12,213 - handlers.py[DEBUG]: finish: init-network/config-users-groups: SUCCESS: config-users-groups ran successfully
2021-12-07 11:06:12,213 - stages.py[DEBUG]: Running module ssh (<module 'cloudinit.config.cc_ssh' from '/usr/lib/python3/dist-packages/cloudinit/config/cc_ssh.py'>) with frequency once-per-instance
2021-12-07 11:06:12,213 - handlers.py[DEBUG]: start: init-network/config-ssh: running config-ssh with frequency once-per-instance
2021-12-07 11:06:12,214 - util.py[DEBUG]: Writing to /var/lib/cloud/instances/9d5276fc-2736-a348-9ee7-95af558790ea/sem/config_ssh - wb: [644] 24 bytes
2021-12-07 11:06:12,214 - helpers.py[DEBUG]: Running config-ssh using lock (<FileLock using file '/var/lib/cloud/instances/9d5276fc-2736-a348-9ee7-95af558790ea/sem/config_ssh'>)
2021-12-07 11:06:12,215 - subp.py[DEBUG]: Running command ['ssh-keygen', '-t', 'rsa', '-N', '', '-f', '/etc/ssh/ssh_host_rsa_key'] with allowed return codes [0] (shell=False, capture=True)
2021-12-07 11:06:12,382 - util.py[DEBUG]: Group ssh_keys is not a valid group name
2021-12-07 11:06:12,382 - subp.py[DEBUG]: Running command ['ssh-keygen', '-t', 'dsa', '-N', '', '-f', '/etc/ssh/ssh_host_dsa_key'] with allowed return codes [0] (shell=False, capture=True)
2021-12-07 11:06:12,428 - util.py[DEBUG]: Group ssh_keys is not a valid group name
2021-12-07 11:06:12,429 - subp.py[DEBUG]: Running command ['ssh-keygen', '-t', 'ecdsa', '-N', '', '-f', '/etc/ssh/ssh_host_ecdsa_key'] with allowed return codes [0] (shell=False, capture=True)
2021-12-07 11:06:12,439 - util.py[DEBUG]: Group ssh_keys is not a valid group name
2021-12-07 11:06:12,440 - subp.py[DEBUG]: Running command ['ssh-keygen', '-t', 'ed25519', '-N', '', '-f', '/etc/ssh/ssh_host_ed25519_key'] with allowed return codes [0] (shell=False, capture=True)
2021-12-07 11:06:12,448 - util.py[DEBUG]: Group ssh_keys is not a valid group name
2021-12-07 11:06:12,449 - util.py[DEBUG]: Reading from /etc/ssh/ssh_host_ecdsa_key.pub (quiet=False)
2021-12-07 11:06:12,449 - util.py[DEBUG]: Read 177 bytes from /etc/ssh/ssh_host_ecdsa_key.pub
2021-12-07 11:06:12,449 - util.py[DEBUG]: Reading from /etc/ssh/ssh_host_ed25519_key.pub (quiet=False)
2021-12-07 11:06:12,449 - util.py[DEBUG]: Read 97 bytes from /etc/ssh/ssh_host_ed25519_key.pub
2021-12-07 11:06:12,449 - util.py[DEBUG]: Reading from /etc/ssh/ssh_host_rsa_key.pub (quiet=False)
2021-12-07 11:06:12,449 - util.py[DEBUG]: Read 397 bytes from /etc/ssh/ssh_host_rsa_key.pub
2021-12-07 11:06:12,450 - handlers.py[DEBUG]: start: azure-ds/get_public_ssh_keys: get_public_ssh_keys
2021-12-07 11:06:12,451 - DataSourceAzure.py[DEBUG]: Retrieving public SSH keys
2021-12-07 11:06:12,451 - DataSourceAzure.py[DEBUG]: Attempting to get SSH keys from IMDS
2021-12-07 11:06:12,451 - azure.py[DEBUG]: Retrieved 0 keys from IMDS
2021-12-07 11:06:12,451 - handlers.py[DEBUG]: finish: azure-ds/get_public_ssh_keys: SUCCESS: get_public_ssh_keys
2021-12-07 11:06:12,452 - util.py[DEBUG]: Reading from /etc/ssh/sshd_config (quiet=False)
2021-12-07 11:06:12,452 - util.py[DEBUG]: Read 3364 bytes from /etc/ssh/sshd_config
2021-12-07 11:06:12,453 - util.py[DEBUG]: Changing the ownership of /home/devGrafanaDashboard/.ssh to 1000:1000
2021-12-07 11:06:12,453 - util.py[DEBUG]: Writing to /home/devGrafanaDashboard/.ssh/authorized_keys - wb: [600] 0 bytes
2021-12-07 11:06:12,454 - util.py[DEBUG]: Changing the ownership of /home/devGrafanaDashboard/.ssh/authorized_keys to 1000:1000
2021-12-07 11:06:12,454 - util.py[DEBUG]: Reading from /home/devGrafanaDashboard/.ssh/authorized_keys (quiet=False)
2021-12-07 11:06:12,454 - util.py[DEBUG]: Read 0 bytes from /home/devGrafanaDashboard/.ssh/authorized_keys
2021-12-07 11:06:12,454 - util.py[DEBUG]: Writing to /home/devGrafanaDashboard/.ssh/authorized_keys - wb: [600] 0 bytes
2021-12-07 11:06:12,455 - util.py[DEBUG]: Reading from /etc/ssh/sshd_config (quiet=False)
2021-12-07 11:06:12,455 - util.py[DEBUG]: Read 3364 bytes from /etc/ssh/sshd_config
2021-12-07 11:06:12,455 - util.py[DEBUG]: Changing the ownership of /root/.ssh to 0:0
2021-12-07 11:06:12,456 - util.py[DEBUG]: Writing to /root/.ssh/authorized_keys - wb: [600] 0 bytes
2021-12-07 11:06:12,456 - util.py[DEBUG]: Changing the ownership of /root/.ssh/authorized_keys to 0:0
2021-12-07 11:06:12,456 - util.py[DEBUG]: Reading from /root/.ssh/authorized_keys (quiet=False)
2021-12-07 11:06:12,456 - util.py[DEBUG]: Read 0 bytes from /root/.ssh/authorized_keys
2021-12-07 11:06:12,456 - util.py[DEBUG]: Writing to /root/.ssh/authorized_keys - wb: [600] 0 bytes
2021-12-07 11:06:12,457 - handlers.py[DEBUG]: finish: init-network/config-ssh: SUCCESS: config-ssh ran successfully
2021-12-07 11:06:12,457 - main.py[DEBUG]: Ran 15 modules with 0 failures
2021-12-07 11:06:12,458 - atomic_helper.py[DEBUG]: Atomically writing to file /var/lib/cloud/data/status.json (via temporary file /var/lib/cloud/data/tmp0cju3a63) - w: [644] 532 bytes/chars
2021-12-07 11:06:12,458 - util.py[DEBUG]: Reading from /proc/uptime (quiet=False)
2021-12-07 11:06:12,458 - util.py[DEBUG]: Read 11 bytes from /proc/uptime
2021-12-07 11:06:12,459 - util.py[DEBUG]: cloud-init mode 'init' took 4.517 seconds (4.52)
2021-12-07 11:06:12,459 - handlers.py[DEBUG]: HyperVReportingHandler flushing remaining events
2021-12-07 11:06:12,459 - handlers.py[DEBUG]: finish: init-network: SUCCESS: searching for network datasources
2021-12-07 11:06:17,551 - util.py[DEBUG]: Reading from /proc/uptime (quiet=False)
2021-12-07 11:06:17,552 - util.py[DEBUG]: Read 11 bytes from /proc/uptime
2021-12-07 11:06:17,552 - util.py[DEBUG]: Reading from /proc/uptime (quiet=False)
2021-12-07 11:06:17,552 - util.py[DEBUG]: Read 11 bytes from /proc/uptime
2021-12-07 11:06:17,553 - util.py[DEBUG]: Cloud-init v. 21.4-0ubuntu1~18.04.1 running 'modules:config' at Tue, 07 Dec 2021 11:06:17 +0000. Up 26.70 seconds.
2021-12-07 11:06:17,575 - stages.py[DEBUG]: Using distro class <class 'cloudinit.distros.ubuntu.Distro'>
2021-12-07 11:06:17,576 - stages.py[DEBUG]: Running module emit_upstart (<module 'cloudinit.config.cc_emit_upstart' from '/usr/lib/python3/dist-packages/cloudinit/config/cc_emit_upstart.py'>) with frequency always
2021-12-07 11:06:17,576 - handlers.py[DEBUG]: start: modules-config/config-emit_upstart: running config-emit_upstart with frequency always
2021-12-07 11:06:17,576 - helpers.py[DEBUG]: Running config-emit_upstart using lock (<cloudinit.helpers.DummyLock object at 0x7f91d8ea1160>)
2021-12-07 11:06:17,577 - cc_emit_upstart.py[DEBUG]: no /sbin/initctl located
2021-12-07 11:06:17,577 - cc_emit_upstart.py[DEBUG]: not upstart system, 'emit_upstart' disabled
2021-12-07 11:06:17,577 - handlers.py[DEBUG]: finish: modules-config/config-emit_upstart: SUCCESS: config-emit_upstart ran successfully
2021-12-07 11:06:17,577 - stages.py[DEBUG]: Running module snap (<module 'cloudinit.config.cc_snap' from '/usr/lib/python3/dist-packages/cloudinit/config/cc_snap.py'>) with frequency once-per-instance
2021-12-07 11:06:17,577 - handlers.py[DEBUG]: start: modules-config/config-snap: running config-snap with frequency once-per-instance
2021-12-07 11:06:17,578 - util.py[DEBUG]: Writing to /var/lib/cloud/instances/9d5276fc-2736-a348-9ee7-95af558790ea/sem/config_snap - wb: [644] 25 bytes
2021-12-07 11:06:17,578 - helpers.py[DEBUG]: Running config-snap using lock (<FileLock using file '/var/lib/cloud/instances/9d5276fc-2736-a348-9ee7-95af558790ea/sem/config_snap'>)
2021-12-07 11:06:17,578 - cc_snap.py[DEBUG]: Skipping module named snap, no 'snap' key in configuration
2021-12-07 11:06:17,578 - handlers.py[DEBUG]: finish: modules-config/config-snap: SUCCESS: config-snap ran successfully
2021-12-07 11:06:17,578 - stages.py[DEBUG]: Running module ssh-import-id (<module 'cloudinit.config.cc_ssh_import_id' from '/usr/lib/python3/dist-packages/cloudinit/config/cc_ssh_import_id.py'>) with frequency once-per-instance
2021-12-07 11:06:17,579 - handlers.py[DEBUG]: start: modules-config/config-ssh-import-id: running config-ssh-import-id with frequency once-per-instance
2021-12-07 11:06:17,579 - util.py[DEBUG]: Writing to /var/lib/cloud/instances/9d5276fc-2736-a348-9ee7-95af558790ea/sem/config_ssh_import_id - wb: [644] 25 bytes
2021-12-07 11:06:17,580 - helpers.py[DEBUG]: Running config-ssh-import-id using lock (<FileLock using file '/var/lib/cloud/instances/9d5276fc-2736-a348-9ee7-95af558790ea/sem/config_ssh_import_id'>)
2021-12-07 11:06:17,580 - handlers.py[DEBUG]: finish: modules-config/config-ssh-import-id: SUCCESS: config-ssh-import-id ran successfully
2021-12-07 11:06:17,580 - stages.py[DEBUG]: Running module locale (<module 'cloudinit.config.cc_locale' from '/usr/lib/python3/dist-packages/cloudinit/config/cc_locale.py'>) with frequency once-per-instance
2021-12-07 11:06:17,580 - handlers.py[DEBUG]: start: modules-config/config-locale: running config-locale with frequency once-per-instance
2021-12-07 11:06:17,581 - util.py[DEBUG]: Writing to /var/lib/cloud/instances/9d5276fc-2736-a348-9ee7-95af558790ea/sem/config_locale - wb: [644] 25 bytes
2021-12-07 11:06:17,581 - helpers.py[DEBUG]: Running config-locale using lock (<FileLock using file '/var/lib/cloud/instances/9d5276fc-2736-a348-9ee7-95af558790ea/sem/config_locale'>)
2021-12-07 11:06:17,581 - util.py[DEBUG]: Reading from /etc/default/locale (quiet=False)
2021-12-07 11:06:17,581 - util.py[DEBUG]: Read 13 bytes from /etc/default/locale
2021-12-07 11:06:17,586 - cc_locale.py[DEBUG]: Setting locale to C.UTF-8
2021-12-07 11:06:17,586 - debian.py[DEBUG]: System has 'LANG=C.UTF-8' requested 'C.UTF-8', skipping regeneration.
2021-12-07 11:06:17,586 - handlers.py[DEBUG]: finish: modules-config/config-locale: SUCCESS: config-locale ran successfully
2021-12-07 11:06:17,586 - stages.py[DEBUG]: Running module set-passwords (<module 'cloudinit.config.cc_set_passwords' from '/usr/lib/python3/dist-packages/cloudinit/config/cc_set_passwords.py'>) with frequency once-per-instance
2021-12-07 11:06:17,587 - handlers.py[DEBUG]: start: modules-config/config-set-passwords: running config-set-passwords with frequency once-per-instance
2021-12-07 11:06:17,587 - util.py[DEBUG]: Writing to /var/lib/cloud/instances/9d5276fc-2736-a348-9ee7-95af558790ea/sem/config_set_passwords - wb: [644] 24 bytes
2021-12-07 11:06:17,588 - helpers.py[DEBUG]: Running config-set-passwords using lock (<FileLock using file '/var/lib/cloud/instances/9d5276fc-2736-a348-9ee7-95af558790ea/sem/config_set_passwords'>)
2021-12-07 11:06:17,588 - cc_set_passwords.py[DEBUG]: Setting hashed password for ['devGrafanaDashboard']:
2021-12-07 11:06:17,589 - subp.py[DEBUG]: Running command ['chpasswd', '-e'] with allowed return codes [0] (shell=False, capture=True)
2021-12-07 11:06:18,250 - util.py[DEBUG]: Reading from /etc/ssh/sshd_config (quiet=False)
2021-12-07 11:06:18,251 - util.py[DEBUG]: Read 3364 bytes from /etc/ssh/sshd_config
2021-12-07 11:06:18,251 - ssh_util.py[DEBUG]: line 56: option PasswordAuthentication updated no -> yes
2021-12-07 11:06:18,251 - util.py[DEBUG]: Writing to /etc/ssh/sshd_config - wb: [644] 3365 bytes
2021-12-07 11:06:18,252 - subp.py[DEBUG]: Running command ['systemctl', 'restart', 'ssh'] with allowed return codes [0] (shell=False, capture=True)
2021-12-07 11:06:18,361 - cc_set_passwords.py[DEBUG]: Restarted the SSH daemon.
2021-12-07 11:06:18,361 - handlers.py[DEBUG]: finish: modules-config/config-set-passwords: SUCCESS: config-set-passwords ran successfully
2021-12-07 11:06:18,362 - stages.py[DEBUG]: Running module grub-dpkg (<module 'cloudinit.config.cc_grub_dpkg' from '/usr/lib/python3/dist-packages/cloudinit/config/cc_grub_dpkg.py'>) with frequency once-per-instance
2021-12-07 11:06:18,362 - handlers.py[DEBUG]: start: modules-config/config-grub-dpkg: running config-grub-dpkg with frequency once-per-instance
2021-12-07 11:06:18,363 - util.py[DEBUG]: Writing to /var/lib/cloud/instances/9d5276fc-2736-a348-9ee7-95af558790ea/sem/config_grub_dpkg - wb: [644] 24 bytes
2021-12-07 11:06:18,363 - helpers.py[DEBUG]: Running config-grub-dpkg using lock (<FileLock using file '/var/lib/cloud/instances/9d5276fc-2736-a348-9ee7-95af558790ea/sem/config_grub_dpkg'>)
2021-12-07 11:06:18,364 - subp.py[DEBUG]: Running command ['grub-probe', '-t', 'disk', '/boot'] with allowed return codes [0] (shell=False, capture=True)
2021-12-07 11:06:18,455 - subp.py[DEBUG]: Running command ['udevadm', 'info', '--root', '--query=symlink', '/dev/sda'] with allowed return codes [0] (shell=False, capture=True)
2021-12-07 11:06:18,459 - cc_grub_dpkg.py[DEBUG]: considering these device symlinks: /dev/disk/azure/root,/dev/disk/by-id/scsi-360022480710d5943dd58583d6a9a9f65,/dev/disk/by-id/wwn-0x60022480710d5943dd58583d6a9a9f65,/dev/disk/by-path/acpi-VMBUS:01-scsi-0:0:0:0,/dev/disk/cloud/azure_root
2021-12-07 11:06:18,460 - cc_grub_dpkg.py[DEBUG]: filtered to these disk/by-id symlinks: /dev/disk/by-id/scsi-360022480710d5943dd58583d6a9a9f65,/dev/disk/by-id/wwn-0x60022480710d5943dd58583d6a9a9f65
2021-12-07 11:06:18,460 - cc_grub_dpkg.py[DEBUG]: selected /dev/disk/by-id/scsi-360022480710d5943dd58583d6a9a9f65
2021-12-07 11:06:18,460 - cc_grub_dpkg.py[DEBUG]: Setting grub debconf-set-selections with '/dev/disk/by-id/scsi-360022480710d5943dd58583d6a9a9f65','false'
2021-12-07 11:06:18,460 - subp.py[DEBUG]: Running command ['debconf-set-selections'] with allowed return codes [0] (shell=False, capture=True)
2021-12-07 11:06:19,421 - handlers.py[DEBUG]: finish: modules-config/config-grub-dpkg: SUCCESS: config-grub-dpkg ran successfully
2021-12-07 11:06:19,422 - stages.py[DEBUG]: Running module apt-pipelining (<module 'cloudinit.config.cc_apt_pipelining' from '/usr/lib/python3/dist-packages/cloudinit/config/cc_apt_pipelining.py'>) with frequency once-per-instance
2021-12-07 11:06:19,422 - handlers.py[DEBUG]: start: modules-config/config-apt-pipelining: running config-apt-pipelining with frequency once-per-instance
2021-12-07 11:06:19,423 - util.py[DEBUG]: Writing to /var/lib/cloud/instances/9d5276fc-2736-a348-9ee7-95af558790ea/sem/config_apt_pipelining - wb: [644] 25 bytes
2021-12-07 11:06:19,424 - helpers.py[DEBUG]: Running config-apt-pipelining using lock (<FileLock using file '/var/lib/cloud/instances/9d5276fc-2736-a348-9ee7-95af558790ea/sem/config_apt_pipelining'>)
2021-12-07 11:06:19,424 - handlers.py[DEBUG]: finish: modules-config/config-apt-pipelining: SUCCESS: config-apt-pipelining ran successfully
2021-12-07 11:06:19,425 - stages.py[DEBUG]: Running module apt-configure (<module 'cloudinit.config.cc_apt_configure' from '/usr/lib/python3/dist-packages/cloudinit/config/cc_apt_configure.py'>) with frequency once-per-instance
2021-12-07 11:06:19,426 - handlers.py[DEBUG]: start: modules-config/config-apt-configure: running config-apt-configure with frequency once-per-instance
2021-12-07 11:06:19,426 - util.py[DEBUG]: Writing to /var/lib/cloud/instances/9d5276fc-2736-a348-9ee7-95af558790ea/sem/config_apt_configure - wb: [644] 25 bytes
2021-12-07 11:06:19,427 - helpers.py[DEBUG]: Running config-apt-configure using lock (<FileLock using file '/var/lib/cloud/instances/9d5276fc-2736-a348-9ee7-95af558790ea/sem/config_apt_configure'>)
2021-12-07 11:06:19,427 - cc_apt_configure.py[DEBUG]: debconf_selections was not set in config
2021-12-07 11:06:19,427 - util.py[DEBUG]: Reading from /etc/os-release (quiet=True)
2021-12-07 11:06:19,428 - util.py[DEBUG]: Read 386 bytes from /etc/os-release
2021-12-07 11:06:19,428 - util.py[DEBUG]: Reading from /etc/system-image/channel.ini (quiet=True)
2021-12-07 11:06:19,428 - util.py[DEBUG]: Read 0 bytes from /etc/system-image/channel.ini
2021-12-07 11:06:19,428 - cc_apt_configure.py[DEBUG]: handling apt config: {}
2021-12-07 11:06:19,428 - subp.py[DEBUG]: Running command ['lsb_release', '--all'] with allowed return codes [0] (shell=False, capture=True)
2021-12-07 11:06:19,646 - subp.py[DEBUG]: Running command ['dpkg', '--print-architecture'] with allowed return codes [0] (shell=False, capture=True)
2021-12-07 11:06:19,656 - cc_apt_configure.py[DEBUG]: got primary mirror: None
2021-12-07 11:06:19,657 - cc_apt_configure.py[DEBUG]: got security mirror: None
2021-12-07 11:06:19,657 - subp.py[DEBUG]: Running command ['dpkg', '--print-architecture'] with allowed return codes [0] (shell=False, capture=True)
2021-12-07 11:06:19,666 - util.py[DEBUG]: search for mirror in candidates: '['http://azure.archive.ubuntu.com/ubuntu/']'
2021-12-07 11:06:19,704 - util.py[DEBUG]: Resolving URL: http://azure.archive.ubuntu.com/ubuntu/ took 0.037 seconds
2021-12-07 11:06:19,704 - util.py[DEBUG]: found working mirror: 'http://azure.archive.ubuntu.com/ubuntu/'
2021-12-07 11:06:19,704 - util.py[DEBUG]: search for mirror in candidates: '[]'
2021-12-07 11:06:19,704 - __init__.py[DEBUG]: filtered distro mirror info: {'primary': 'http://azure.archive.ubuntu.com/ubuntu/', 'security': 'http://security.ubuntu.com/ubuntu'}
2021-12-07 11:06:19,704 - cc_apt_configure.py[DEBUG]: Apt Mirror info: {'primary': 'http://azure.archive.ubuntu.com/ubuntu/', 'security': 'http://security.ubuntu.com/ubuntu', 'PRIMARY': 'http://azure.archive.ubuntu.com/ubuntu/', 'SECURITY': 'http://security.ubuntu.com/ubuntu', 'MIRROR': 'http://azure.archive.ubuntu.com/ubuntu/'}
2021-12-07 11:06:19,704 - cc_apt_configure.py[INFO]: No custom template provided, fall back to builtin
2021-12-07 11:06:19,705 - util.py[DEBUG]: Reading from /etc/cloud/templates/sources.list.ubuntu.tmpl (quiet=False)
2021-12-07 11:06:19,705 - util.py[DEBUG]: Read 2858 bytes from /etc/cloud/templates/sources.list.ubuntu.tmpl
2021-12-07 11:06:19,723 - util.py[DEBUG]: Writing to /etc/apt/sources.list - wb: [644] 3240 bytes
2021-12-07 11:06:19,726 - cc_apt_configure.py[DEBUG]: Renaming apt list /var/lib/apt/lists/archive.ubuntu.com_ubuntu_dists_bionic-updates_restricted_binary-amd64_Packages to /var/lib/apt/lists/azure.archive.ubuntu.com_ubuntu_dists_bionic-updates_restricted_binary-amd64_Packages
2021-12-07 11:06:19,734 - cc_apt_configure.py[DEBUG]: Renaming apt list /var/lib/apt/lists/archive.ubuntu.com_ubuntu_dists_bionic_main_i18n_Translation-en to /var/lib/apt/lists/azure.archive.ubuntu.com_ubuntu_dists_bionic_main_i18n_Translation-en
2021-12-07 11:06:19,734 - cc_apt_configure.py[DEBUG]: Renaming apt list /var/lib/apt/lists/archive.ubuntu.com_ubuntu_dists_bionic-updates_main_i18n_Translation-en to /var/lib/apt/lists/azure.archive.ubuntu.com_ubuntu_dists_bionic-updates_main_i18n_Translation-en
2021-12-07 11:06:19,734 - cc_apt_configure.py[DEBUG]: Renaming apt list /var/lib/apt/lists/archive.ubuntu.com_ubuntu_dists_bionic-updates_main_binary-amd64_Packages to /var/lib/apt/lists/azure.archive.ubuntu.com_ubuntu_dists_bionic-updates_main_binary-amd64_Packages
2021-12-07 11:06:19,734 - cc_apt_configure.py[DEBUG]: Renaming apt list /var/lib/apt/lists/archive.ubuntu.com_ubuntu_dists_bionic_restricted_binary-amd64_Packages to /var/lib/apt/lists/azure.archive.ubuntu.com_ubuntu_dists_bionic_restricted_binary-amd64_Packages
2021-12-07 11:06:19,734 - cc_apt_configure.py[DEBUG]: Renaming apt list /var/lib/apt/lists/archive.ubuntu.com_ubuntu_dists_bionic_main_binary-amd64_Packages to /var/lib/apt/lists/azure.archive.ubuntu.com_ubuntu_dists_bionic_main_binary-amd64_Packages
2021-12-07 11:06:19,734 - cc_apt_configure.py[DEBUG]: Renaming apt list /var/lib/apt/lists/archive.ubuntu.com_ubuntu_dists_bionic_InRelease to /var/lib/apt/lists/azure.archive.ubuntu.com_ubuntu_dists_bionic_InRelease
2021-12-07 11:06:19,734 - cc_apt_configure.py[DEBUG]: Renaming apt list /var/lib/apt/lists/archive.ubuntu.com_ubuntu_dists_bionic-updates_restricted_i18n_Translation-en to /var/lib/apt/lists/azure.archive.ubuntu.com_ubuntu_dists_bionic-updates_restricted_i18n_Translation-en
2021-12-07 11:06:19,734 - cc_apt_configure.py[DEBUG]: Renaming apt list /var/lib/apt/lists/archive.ubuntu.com_ubuntu_dists_bionic-updates_InRelease to /var/lib/apt/lists/azure.archive.ubuntu.com_ubuntu_dists_bionic-updates_InRelease
2021-12-07 11:06:19,734 - cc_apt_configure.py[DEBUG]: Renaming apt list /var/lib/apt/lists/archive.ubuntu.com_ubuntu_dists_bionic_restricted_i18n_Translation-en to /var/lib/apt/lists/azure.archive.ubuntu.com_ubuntu_dists_bionic_restricted_i18n_Translation-en
2021-12-07 11:06:19,735 - handlers.py[DEBUG]: finish: modules-config/config-apt-configure: SUCCESS: config-apt-configure ran successfully
2021-12-07 11:06:19,735 - stages.py[DEBUG]: Running module ubuntu-advantage (<module 'cloudinit.config.cc_ubuntu_advantage' from '/usr/lib/python3/dist-packages/cloudinit/config/cc_ubuntu_advantage.py'>) with frequency once-per-instance
2021-12-07 11:06:19,742 - handlers.py[DEBUG]: start: modules-config/config-ubuntu-advantage: running config-ubuntu-advantage with frequency once-per-instance
2021-12-07 11:06:19,742 - util.py[DEBUG]: Writing to /var/lib/cloud/instances/9d5276fc-2736-a348-9ee7-95af558790ea/sem/config_ubuntu_advantage - wb: [644] 24 bytes
2021-12-07 11:06:19,743 - helpers.py[DEBUG]: Running config-ubuntu-advantage using lock (<FileLock using file '/var/lib/cloud/instances/9d5276fc-2736-a348-9ee7-95af558790ea/sem/config_ubuntu_advantage'>)
2021-12-07 11:06:19,743 - cc_ubuntu_advantage.py[DEBUG]: Skipping module named ubuntu-advantage, no 'ubuntu_advantage' configuration found
2021-12-07 11:06:19,743 - handlers.py[DEBUG]: finish: modules-config/config-ubuntu-advantage: SUCCESS: config-ubuntu-advantage ran successfully
2021-12-07 11:06:19,745 - stages.py[DEBUG]: Running module ntp (<module 'cloudinit.config.cc_ntp' from '/usr/lib/python3/dist-packages/cloudinit/config/cc_ntp.py'>) with frequency once-per-instance
2021-12-07 11:06:19,746 - handlers.py[DEBUG]: start: modules-config/config-ntp: running config-ntp with frequency once-per-instance
2021-12-07 11:06:19,747 - util.py[DEBUG]: Writing to /var/lib/cloud/instances/9d5276fc-2736-a348-9ee7-95af558790ea/sem/config_ntp - wb: [644] 24 bytes
2021-12-07 11:06:19,748 - helpers.py[DEBUG]: Running config-ntp using lock (<FileLock using file '/var/lib/cloud/instances/9d5276fc-2736-a348-9ee7-95af558790ea/sem/config_ntp'>)
2021-12-07 11:06:19,748 - cc_ntp.py[DEBUG]: Skipping module named ntp, not present or disabled by cfg
2021-12-07 11:06:19,748 - handlers.py[DEBUG]: finish: modules-config/config-ntp: SUCCESS: config-ntp ran successfully
2021-12-07 11:06:19,749 - stages.py[DEBUG]: Running module timezone (<module 'cloudinit.config.cc_timezone' from '/usr/lib/python3/dist-packages/cloudinit/config/cc_timezone.py'>) with frequency once-per-instance
2021-12-07 11:06:19,750 - handlers.py[DEBUG]: start: modules-config/config-timezone: running config-timezone with frequency once-per-instance
2021-12-07 11:06:19,750 - util.py[DEBUG]: Writing to /var/lib/cloud/instances/9d5276fc-2736-a348-9ee7-95af558790ea/sem/config_timezone - wb: [644] 25 bytes
2021-12-07 11:06:19,751 - helpers.py[DEBUG]: Running config-timezone using lock (<FileLock using file '/var/lib/cloud/instances/9d5276fc-2736-a348-9ee7-95af558790ea/sem/config_timezone'>)
2021-12-07 11:06:19,751 - cc_timezone.py[DEBUG]: Skipping module named timezone, no 'timezone' specified
2021-12-07 11:06:19,751 - handlers.py[DEBUG]: finish: modules-config/config-timezone: SUCCESS: config-timezone ran successfully
2021-12-07 11:06:19,753 - stages.py[DEBUG]: Running module disable-ec2-metadata (<module 'cloudinit.config.cc_disable_ec2_metadata' from '/usr/lib/python3/dist-packages/cloudinit/config/cc_disable_ec2_metadata.py'>) with frequency always
2021-12-07 11:06:19,754 - handlers.py[DEBUG]: start: modules-config/config-disable-ec2-metadata: running config-disable-ec2-metadata with frequency always
2021-12-07 11:06:19,754 - helpers.py[DEBUG]: Running config-disable-ec2-metadata using lock (<cloudinit.helpers.DummyLock object at 0x7f91d85e0b70>)
2021-12-07 11:06:19,754 - cc_disable_ec2_metadata.py[DEBUG]: Skipping module named disable-ec2-metadata, disabling the ec2 route not enabled
2021-12-07 11:06:19,754 - handlers.py[DEBUG]: finish: modules-config/config-disable-ec2-metadata: SUCCESS: config-disable-ec2-metadata ran successfully
2021-12-07 11:06:19,755 - stages.py[DEBUG]: Running module runcmd (<module 'cloudinit.config.cc_runcmd' from '/usr/lib/python3/dist-packages/cloudinit/config/cc_runcmd.py'>) with frequency once-per-instance
2021-12-07 11:06:19,755 - handlers.py[DEBUG]: start: modules-config/config-runcmd: running config-runcmd with frequency once-per-instance
2021-12-07 11:06:19,755 - util.py[DEBUG]: Writing to /var/lib/cloud/instances/9d5276fc-2736-a348-9ee7-95af558790ea/sem/config_runcmd - wb: [644] 25 bytes
2021-12-07 11:06:19,756 - helpers.py[DEBUG]: Running config-runcmd using lock (<FileLock using file '/var/lib/cloud/instances/9d5276fc-2736-a348-9ee7-95af558790ea/sem/config_runcmd'>)
2021-12-07 11:06:19,756 - cc_runcmd.py[DEBUG]: Skipping module named runcmd, no 'runcmd' key in configuration
2021-12-07 11:06:19,756 - handlers.py[DEBUG]: finish: modules-config/config-runcmd: SUCCESS: config-runcmd ran successfully
2021-12-07 11:06:19,758 - stages.py[DEBUG]: Running module byobu (<module 'cloudinit.config.cc_byobu' from '/usr/lib/python3/dist-packages/cloudinit/config/cc_byobu.py'>) with frequency once-per-instance
2021-12-07 11:06:19,758 - handlers.py[DEBUG]: start: modules-config/config-byobu: running config-byobu with frequency once-per-instance
2021-12-07 11:06:19,758 - util.py[DEBUG]: Writing to /var/lib/cloud/instances/9d5276fc-2736-a348-9ee7-95af558790ea/sem/config_byobu - wb: [644] 25 bytes
2021-12-07 11:06:19,759 - helpers.py[DEBUG]: Running config-byobu using lock (<FileLock using file '/var/lib/cloud/instances/9d5276fc-2736-a348-9ee7-95af558790ea/sem/config_byobu'>)
2021-12-07 11:06:19,759 - cc_byobu.py[DEBUG]: Skipping module named byobu, no 'byobu' values found
2021-12-07 11:06:19,759 - handlers.py[DEBUG]: finish: modules-config/config-byobu: SUCCESS: config-byobu ran successfully
2021-12-07 11:06:19,761 - main.py[DEBUG]: Ran 14 modules with 0 failures
2021-12-07 11:06:19,762 - atomic_helper.py[DEBUG]: Atomically writing to file /var/lib/cloud/data/status.json (via temporary file /var/lib/cloud/data/tmp6pxyaeol) - w: [644] 559 bytes/chars
2021-12-07 11:06:19,762 - util.py[DEBUG]: Reading from /proc/uptime (quiet=False)
2021-12-07 11:06:19,763 - util.py[DEBUG]: Read 11 bytes from /proc/uptime
2021-12-07 11:06:19,763 - util.py[DEBUG]: cloud-init mode 'modules' took 2.310 seconds (2.31)
2021-12-07 11:06:19,763 - handlers.py[DEBUG]: HyperVReportingHandler flushing remaining events
2021-12-07 11:06:19,763 - handlers.py[DEBUG]: finish: modules-config: SUCCESS: running modules for config
2021-12-07 11:06:21,111 - util.py[DEBUG]: Reading from /proc/uptime (quiet=False)
2021-12-07 11:06:21,111 - util.py[DEBUG]: Read 11 bytes from /proc/uptime
2021-12-07 11:06:21,112 - util.py[DEBUG]: Reading from /proc/uptime (quiet=False)
2021-12-07 11:06:21,112 - util.py[DEBUG]: Read 11 bytes from /proc/uptime
2021-12-07 11:06:21,113 - util.py[DEBUG]: Cloud-init v. 21.4-0ubuntu1~18.04.1 running 'modules:final' at Tue, 07 Dec 2021 11:06:21 +0000. Up 30.26 seconds.
2021-12-07 11:06:21,137 - stages.py[DEBUG]: Using distro class <class 'cloudinit.distros.ubuntu.Distro'>
2021-12-07 11:06:21,138 - stages.py[DEBUG]: Running module package-update-upgrade-install (<module 'cloudinit.config.cc_package_update_upgrade_install' from '/usr/lib/python3/dist-packages/cloudinit/config/cc_package_update_upgrade_install.py'>) with frequency once-per-instance
2021-12-07 11:06:21,139 - handlers.py[DEBUG]: start: modules-final/config-package-update-upgrade-install: running config-package-update-upgrade-install with frequency once-per-instance
2021-12-07 11:06:21,139 - util.py[DEBUG]: Writing to /var/lib/cloud/instances/9d5276fc-2736-a348-9ee7-95af558790ea/sem/config_package_update_upgrade_install - wb: [644] 25 bytes
2021-12-07 11:06:21,140 - helpers.py[DEBUG]: Running config-package-update-upgrade-install using lock (<FileLock using file '/var/lib/cloud/instances/9d5276fc-2736-a348-9ee7-95af558790ea/sem/config_package_update_upgrade_install'>)
2021-12-07 11:06:21,140 - handlers.py[DEBUG]: finish: modules-final/config-package-update-upgrade-install: SUCCESS: config-package-update-upgrade-install ran successfully
2021-12-07 11:06:21,140 - stages.py[DEBUG]: Running module fan (<module 'cloudinit.config.cc_fan' from '/usr/lib/python3/dist-packages/cloudinit/config/cc_fan.py'>) with frequency once-per-instance
2021-12-07 11:06:21,140 - handlers.py[DEBUG]: start: modules-final/config-fan: running config-fan with frequency once-per-instance
2021-12-07 11:06:21,141 - util.py[DEBUG]: Writing to /var/lib/cloud/instances/9d5276fc-2736-a348-9ee7-95af558790ea/sem/config_fan - wb: [644] 25 bytes
2021-12-07 11:06:21,141 - helpers.py[DEBUG]: Running config-fan using lock (<FileLock using file '/var/lib/cloud/instances/9d5276fc-2736-a348-9ee7-95af558790ea/sem/config_fan'>)
2021-12-07 11:06:21,141 - cc_fan.py[DEBUG]: fan: no 'fan' config entry. disabling
2021-12-07 11:06:21,142 - handlers.py[DEBUG]: finish: modules-final/config-fan: SUCCESS: config-fan ran successfully
2021-12-07 11:06:21,142 - stages.py[DEBUG]: Running module landscape (<module 'cloudinit.config.cc_landscape' from '/usr/lib/python3/dist-packages/cloudinit/config/cc_landscape.py'>) with frequency once-per-instance
2021-12-07 11:06:21,142 - handlers.py[DEBUG]: start: modules-final/config-landscape: running config-landscape with frequency once-per-instance
2021-12-07 11:06:21,142 - util.py[DEBUG]: Writing to /var/lib/cloud/instances/9d5276fc-2736-a348-9ee7-95af558790ea/sem/config_landscape - wb: [644] 25 bytes
2021-12-07 11:06:21,143 - helpers.py[DEBUG]: Running config-landscape using lock (<FileLock using file '/var/lib/cloud/instances/9d5276fc-2736-a348-9ee7-95af558790ea/sem/config_landscape'>)
2021-12-07 11:06:21,143 - handlers.py[DEBUG]: finish: modules-final/config-landscape: SUCCESS: config-landscape ran successfully
2021-12-07 11:06:21,143 - stages.py[DEBUG]: Running module lxd (<module 'cloudinit.config.cc_lxd' from '/usr/lib/python3/dist-packages/cloudinit/config/cc_lxd.py'>) with frequency once-per-instance
2021-12-07 11:06:21,143 - handlers.py[DEBUG]: start: modules-final/config-lxd: running config-lxd with frequency once-per-instance
2021-12-07 11:06:21,144 - util.py[DEBUG]: Writing to /var/lib/cloud/instances/9d5276fc-2736-a348-9ee7-95af558790ea/sem/config_lxd - wb: [644] 25 bytes
2021-12-07 11:06:21,144 - helpers.py[DEBUG]: Running config-lxd using lock (<FileLock using file '/var/lib/cloud/instances/9d5276fc-2736-a348-9ee7-95af558790ea/sem/config_lxd'>)
2021-12-07 11:06:21,144 - cc_lxd.py[DEBUG]: Skipping module named lxd, not present or disabled by cfg
2021-12-07 11:06:21,144 - handlers.py[DEBUG]: finish: modules-final/config-lxd: SUCCESS: config-lxd ran successfully
2021-12-07 11:06:21,144 - stages.py[DEBUG]: Running module ubuntu-drivers (<module 'cloudinit.config.cc_ubuntu_drivers' from '/usr/lib/python3/dist-packages/cloudinit/config/cc_ubuntu_drivers.py'>) with frequency once-per-instance
2021-12-07 11:06:21,145 - handlers.py[DEBUG]: start: modules-final/config-ubuntu-drivers: running config-ubuntu-drivers with frequency once-per-instance
2021-12-07 11:06:21,145 - util.py[DEBUG]: Writing to /var/lib/cloud/instances/9d5276fc-2736-a348-9ee7-95af558790ea/sem/config_ubuntu_drivers - wb: [644] 25 bytes
2021-12-07 11:06:21,145 - helpers.py[DEBUG]: Running config-ubuntu-drivers using lock (<FileLock using file '/var/lib/cloud/instances/9d5276fc-2736-a348-9ee7-95af558790ea/sem/config_ubuntu_drivers'>)
2021-12-07 11:06:21,146 - cc_ubuntu_drivers.py[DEBUG]: Skipping module named ubuntu-drivers, no 'drivers' key in config
2021-12-07 11:06:21,146 - handlers.py[DEBUG]: finish: modules-final/config-ubuntu-drivers: SUCCESS: config-ubuntu-drivers ran successfully
2021-12-07 11:06:21,146 - stages.py[DEBUG]: Running module write-files-deferred (<module 'cloudinit.config.cc_write_files_deferred' from '/usr/lib/python3/dist-packages/cloudinit/config/cc_write_files_deferred.py'>) with frequency once-per-instance
2021-12-07 11:06:21,146 - handlers.py[DEBUG]: start: modules-final/config-write-files-deferred: running config-write-files-deferred with frequency once-per-instance
2021-12-07 11:06:21,146 - util.py[DEBUG]: Writing to /var/lib/cloud/instances/9d5276fc-2736-a348-9ee7-95af558790ea/sem/config_write_files_deferred - wb: [644] 25 bytes
2021-12-07 11:06:21,147 - helpers.py[DEBUG]: Running config-write-files-deferred using lock (<FileLock using file '/var/lib/cloud/instances/9d5276fc-2736-a348-9ee7-95af558790ea/sem/config_write_files_deferred'>)
2021-12-07 11:06:21,152 - cc_write_files_deferred.py[DEBUG]: Skipping module named write-files-deferred, no deferred file defined in configuration
2021-12-07 11:06:21,152 - handlers.py[DEBUG]: finish: modules-final/config-write-files-deferred: SUCCESS: config-write-files-deferred ran successfully
2021-12-07 11:06:21,152 - stages.py[DEBUG]: Running module puppet (<module 'cloudinit.config.cc_puppet' from '/usr/lib/python3/dist-packages/cloudinit/config/cc_puppet.py'>) with frequency once-per-instance
2021-12-07 11:06:21,152 - handlers.py[DEBUG]: start: modules-final/config-puppet: running config-puppet with frequency once-per-instance
2021-12-07 11:06:21,153 - util.py[DEBUG]: Writing to /var/lib/cloud/instances/9d5276fc-2736-a348-9ee7-95af558790ea/sem/config_puppet - wb: [644] 25 bytes
2021-12-07 11:06:21,153 - helpers.py[DEBUG]: Running config-puppet using lock (<FileLock using file '/var/lib/cloud/instances/9d5276fc-2736-a348-9ee7-95af558790ea/sem/config_puppet'>)
2021-12-07 11:06:21,153 - cc_puppet.py[DEBUG]: Skipping module named puppet, no 'puppet' configuration found
2021-12-07 11:06:21,153 - handlers.py[DEBUG]: finish: modules-final/config-puppet: SUCCESS: config-puppet ran successfully
2021-12-07 11:06:21,153 - stages.py[DEBUG]: Running module chef (<module 'cloudinit.config.cc_chef' from '/usr/lib/python3/dist-packages/cloudinit/config/cc_chef.py'>) with frequency always
2021-12-07 11:06:21,154 - handlers.py[DEBUG]: start: modules-final/config-chef: running config-chef with frequency always
2021-12-07 11:06:21,154 - helpers.py[DEBUG]: Running config-chef using lock (<cloudinit.helpers.DummyLock object at 0x7fbd65651e48>)
2021-12-07 11:06:21,154 - cc_chef.py[DEBUG]: Skipping module named chef, no 'chef' key in configuration
2021-12-07 11:06:21,154 - handlers.py[DEBUG]: finish: modules-final/config-chef: SUCCESS: config-chef ran successfully
2021-12-07 11:06:21,154 - stages.py[DEBUG]: Running module mcollective (<module 'cloudinit.config.cc_mcollective' from '/usr/lib/python3/dist-packages/cloudinit/config/cc_mcollective.py'>) with frequency once-per-instance
2021-12-07 11:06:21,155 - handlers.py[DEBUG]: start: modules-final/config-mcollective: running config-mcollective with frequency once-per-instance
2021-12-07 11:06:21,155 - util.py[DEBUG]: Writing to /var/lib/cloud/instances/9d5276fc-2736-a348-9ee7-95af558790ea/sem/config_mcollective - wb: [644] 25 bytes
2021-12-07 11:06:21,155 - helpers.py[DEBUG]: Running config-mcollective using lock (<FileLock using file '/var/lib/cloud/instances/9d5276fc-2736-a348-9ee7-95af558790ea/sem/config_mcollective'>)
2021-12-07 11:06:21,156 - cc_mcollective.py[DEBUG]: Skipping module named mcollective, no 'mcollective' key in configuration
2021-12-07 11:06:21,156 - handlers.py[DEBUG]: finish: modules-final/config-mcollective: SUCCESS: config-mcollective ran successfully
2021-12-07 11:06:21,156 - stages.py[DEBUG]: Running module salt-minion (<module 'cloudinit.config.cc_salt_minion' from '/usr/lib/python3/dist-packages/cloudinit/config/cc_salt_minion.py'>) with frequency once-per-instance
2021-12-07 11:06:21,156 - handlers.py[DEBUG]: start: modules-final/config-salt-minion: running config-salt-minion with frequency once-per-instance
2021-12-07 11:06:21,156 - util.py[DEBUG]: Writing to /var/lib/cloud/instances/9d5276fc-2736-a348-9ee7-95af558790ea/sem/config_salt_minion - wb: [644] 25 bytes
2021-12-07 11:06:21,157 - helpers.py[DEBUG]: Running config-salt-minion using lock (<FileLock using file '/var/lib/cloud/instances/9d5276fc-2736-a348-9ee7-95af558790ea/sem/config_salt_minion'>)
2021-12-07 11:06:21,157 - cc_salt_minion.py[DEBUG]: Skipping module named salt-minion, no 'salt_minion' key in configuration
2021-12-07 11:06:21,157 - handlers.py[DEBUG]: finish: modules-final/config-salt-minion: SUCCESS: config-salt-minion ran successfully
2021-12-07 11:06:21,157 - stages.py[DEBUG]: Running module reset_rmc (<module 'cloudinit.config.cc_reset_rmc' from '/usr/lib/python3/dist-packages/cloudinit/config/cc_reset_rmc.py'>) with frequency once-per-instance
2021-12-07 11:06:21,158 - handlers.py[DEBUG]: start: modules-final/config-reset_rmc: running config-reset_rmc with frequency once-per-instance
2021-12-07 11:06:21,158 - util.py[DEBUG]: Writing to /var/lib/cloud/instances/9d5276fc-2736-a348-9ee7-95af558790ea/sem/config_reset_rmc - wb: [644] 23 bytes
2021-12-07 11:06:21,158 - helpers.py[DEBUG]: Running config-reset_rmc using lock (<FileLock using file '/var/lib/cloud/instances/9d5276fc-2736-a348-9ee7-95af558790ea/sem/config_reset_rmc'>)
2021-12-07 11:06:21,159 - cc_reset_rmc.py[DEBUG]: module disabled, RSCT_PATH not present
2021-12-07 11:06:21,159 - handlers.py[DEBUG]: finish: modules-final/config-reset_rmc: SUCCESS: config-reset_rmc ran successfully
2021-12-07 11:06:21,159 - stages.py[DEBUG]: Running module refresh_rmc_and_interface (<module 'cloudinit.config.cc_refresh_rmc_and_interface' from '/usr/lib/python3/dist-packages/cloudinit/config/cc_refresh_rmc_and_interface.py'>) with frequency always
2021-12-07 11:06:21,159 - handlers.py[DEBUG]: start: modules-final/config-refresh_rmc_and_interface: running config-refresh_rmc_and_interface with frequency always
2021-12-07 11:06:21,159 - helpers.py[DEBUG]: Running config-refresh_rmc_and_interface using lock (<cloudinit.helpers.DummyLock object at 0x7fbd65651e80>)
2021-12-07 11:06:21,160 - cc_refresh_rmc_and_interface.py[DEBUG]: No 'rmcctrl' in path, disabled
2021-12-07 11:06:21,160 - handlers.py[DEBUG]: finish: modules-final/config-refresh_rmc_and_interface: SUCCESS: config-refresh_rmc_and_interface ran successfully
2021-12-07 11:06:21,160 - stages.py[DEBUG]: Running module rightscale_userdata (<module 'cloudinit.config.cc_rightscale_userdata' from '/usr/lib/python3/dist-packages/cloudinit/config/cc_rightscale_userdata.py'>) with frequency once-per-instance
2021-12-07 11:06:21,160 - handlers.py[DEBUG]: start: modules-final/config-rightscale_userdata: running config-rightscale_userdata with frequency once-per-instance
2021-12-07 11:06:21,161 - util.py[DEBUG]: Writing to /var/lib/cloud/instances/9d5276fc-2736-a348-9ee7-95af558790ea/sem/config_rightscale_userdata - wb: [644] 25 bytes
2021-12-07 11:06:21,161 - helpers.py[DEBUG]: Running config-rightscale_userdata using lock (<FileLock using file '/var/lib/cloud/instances/9d5276fc-2736-a348-9ee7-95af558790ea/sem/config_rightscale_userdata'>)
2021-12-07 11:06:21,161 - cc_rightscale_userdata.py[DEBUG]: Failed to get raw userdata in module rightscale_userdata
2021-12-07 11:06:21,161 - handlers.py[DEBUG]: finish: modules-final/config-rightscale_userdata: SUCCESS: config-rightscale_userdata ran successfully
2021-12-07 11:06:21,161 - stages.py[DEBUG]: Running module scripts-vendor (<module 'cloudinit.config.cc_scripts_vendor' from '/usr/lib/python3/dist-packages/cloudinit/config/cc_scripts_vendor.py'>) with frequency once-per-instance
2021-12-07 11:06:21,162 - handlers.py[DEBUG]: start: modules-final/config-scripts-vendor: running config-scripts-vendor with frequency once-per-instance
2021-12-07 11:06:21,162 - util.py[DEBUG]: Writing to /var/lib/cloud/instances/9d5276fc-2736-a348-9ee7-95af558790ea/sem/config_scripts_vendor - wb: [644] 25 bytes
2021-12-07 11:06:21,163 - helpers.py[DEBUG]: Running config-scripts-vendor using lock (<FileLock using file '/var/lib/cloud/instances/9d5276fc-2736-a348-9ee7-95af558790ea/sem/config_scripts_vendor'>)
2021-12-07 11:06:21,163 - handlers.py[DEBUG]: finish: modules-final/config-scripts-vendor: SUCCESS: config-scripts-vendor ran successfully
2021-12-07 11:06:21,163 - stages.py[DEBUG]: Running module scripts-per-once (<module 'cloudinit.config.cc_scripts_per_once' from '/usr/lib/python3/dist-packages/cloudinit/config/cc_scripts_per_once.py'>) with frequency once
2021-12-07 11:06:21,163 - handlers.py[DEBUG]: start: modules-final/config-scripts-per-once: running config-scripts-per-once with frequency once
2021-12-07 11:06:21,164 - util.py[DEBUG]: Writing to /var/lib/cloud/sem/config_scripts_per_once.once - wb: [644] 25 bytes
2021-12-07 11:06:21,164 - helpers.py[DEBUG]: Running config-scripts-per-once using lock (<FileLock using file '/var/lib/cloud/sem/config_scripts_per_once.once'>)
2021-12-07 11:06:21,164 - handlers.py[DEBUG]: finish: modules-final/config-scripts-per-once: SUCCESS: config-scripts-per-once ran successfully
2021-12-07 11:06:21,164 - stages.py[DEBUG]: Running module scripts-per-boot (<module 'cloudinit.config.cc_scripts_per_boot' from '/usr/lib/python3/dist-packages/cloudinit/config/cc_scripts_per_boot.py'>) with frequency always
2021-12-07 11:06:21,165 - handlers.py[DEBUG]: start: modules-final/config-scripts-per-boot: running config-scripts-per-boot with frequency always
2021-12-07 11:06:21,165 - helpers.py[DEBUG]: Running config-scripts-per-boot using lock (<cloudinit.helpers.DummyLock object at 0x7fbd655dd128>)
2021-12-07 11:06:21,165 - handlers.py[DEBUG]: finish: modules-final/config-scripts-per-boot: SUCCESS: config-scripts-per-boot ran successfully
2021-12-07 11:06:21,165 - stages.py[DEBUG]: Running module scripts-per-instance (<module 'cloudinit.config.cc_scripts_per_instance' from '/usr/lib/python3/dist-packages/cloudinit/config/cc_scripts_per_instance.py'>) with frequency once-per-instance
2021-12-07 11:06:21,166 - handlers.py[DEBUG]: start: modules-final/config-scripts-per-instance: running config-scripts-per-instance with frequency once-per-instance
2021-12-07 11:06:21,166 - util.py[DEBUG]: Writing to /var/lib/cloud/instances/9d5276fc-2736-a348-9ee7-95af558790ea/sem/config_scripts_per_instance - wb: [644] 25 bytes
2021-12-07 11:06:21,166 - helpers.py[DEBUG]: Running config-scripts-per-instance using lock (<FileLock using file '/var/lib/cloud/instances/9d5276fc-2736-a348-9ee7-95af558790ea/sem/config_scripts_per_instance'>)
2021-12-07 11:06:21,167 - handlers.py[DEBUG]: finish: modules-final/config-scripts-per-instance: SUCCESS: config-scripts-per-instance ran successfully
2021-12-07 11:06:21,167 - stages.py[DEBUG]: Running module scripts-user (<module 'cloudinit.config.cc_scripts_user' from '/usr/lib/python3/dist-packages/cloudinit/config/cc_scripts_user.py'>) with frequency once-per-instance
2021-12-07 11:06:21,167 - handlers.py[DEBUG]: start: modules-final/config-scripts-user: running config-scripts-user with frequency once-per-instance
2021-12-07 11:06:21,167 - util.py[DEBUG]: Writing to /var/lib/cloud/instances/9d5276fc-2736-a348-9ee7-95af558790ea/sem/config_scripts_user - wb: [644] 25 bytes
2021-12-07 11:06:21,168 - helpers.py[DEBUG]: Running config-scripts-user using lock (<FileLock using file '/var/lib/cloud/instances/9d5276fc-2736-a348-9ee7-95af558790ea/sem/config_scripts_user'>)
2021-12-07 11:06:21,168 - handlers.py[DEBUG]: finish: modules-final/config-scripts-user: SUCCESS: config-scripts-user ran successfully
2021-12-07 11:06:21,168 - stages.py[DEBUG]: Running module ssh-authkey-fingerprints (<module 'cloudinit.config.cc_ssh_authkey_fingerprints' from '/usr/lib/python3/dist-packages/cloudinit/config/cc_ssh_authkey_fingerprints.py'>) with frequency once-per-instance
2021-12-07 11:06:21,168 - handlers.py[DEBUG]: start: modules-final/config-ssh-authkey-fingerprints: running config-ssh-authkey-fingerprints with frequency once-per-instance
2021-12-07 11:06:21,169 - util.py[DEBUG]: Writing to /var/lib/cloud/instances/9d5276fc-2736-a348-9ee7-95af558790ea/sem/config_ssh_authkey_fingerprints - wb: [644] 24 bytes
2021-12-07 11:06:21,169 - helpers.py[DEBUG]: Running config-ssh-authkey-fingerprints using lock (<FileLock using file '/var/lib/cloud/instances/9d5276fc-2736-a348-9ee7-95af558790ea/sem/config_ssh_authkey_fingerprints'>)
2021-12-07 11:06:21,170 - util.py[DEBUG]: Reading from /etc/ssh/sshd_config (quiet=False)
2021-12-07 11:06:21,170 - util.py[DEBUG]: Read 3365 bytes from /etc/ssh/sshd_config
2021-12-07 11:06:21,170 - util.py[DEBUG]: Reading from /home/devGrafanaDashboard/.ssh/authorized_keys (quiet=False)
2021-12-07 11:06:21,171 - util.py[DEBUG]: Read 0 bytes from /home/devGrafanaDashboard/.ssh/authorized_keys
2021-12-07 11:06:21,178 - handlers.py[DEBUG]: finish: modules-final/config-ssh-authkey-fingerprints: SUCCESS: config-ssh-authkey-fingerprints ran successfully
2021-12-07 11:06:21,178 - stages.py[DEBUG]: Running module keys-to-console (<module 'cloudinit.config.cc_keys_to_console' from '/usr/lib/python3/dist-packages/cloudinit/config/cc_keys_to_console.py'>) with frequency once-per-instance
2021-12-07 11:06:21,179 - handlers.py[DEBUG]: start: modules-final/config-keys-to-console: running config-keys-to-console with frequency once-per-instance
2021-12-07 11:06:21,179 - util.py[DEBUG]: Writing to /var/lib/cloud/instances/9d5276fc-2736-a348-9ee7-95af558790ea/sem/config_keys_to_console - wb: [644] 25 bytes
2021-12-07 11:06:21,180 - helpers.py[DEBUG]: Running config-keys-to-console using lock (<FileLock using file '/var/lib/cloud/instances/9d5276fc-2736-a348-9ee7-95af558790ea/sem/config_keys_to_console'>)
2021-12-07 11:06:21,180 - subp.py[DEBUG]: Running command ['/usr/lib/cloud-init/write-ssh-key-fingerprints', '', 'ssh-dss'] with allowed return codes [0] (shell=False, capture=True)
2021-12-07 11:06:21,223 - handlers.py[DEBUG]: finish: modules-final/config-keys-to-console: SUCCESS: config-keys-to-console ran successfully
2021-12-07 11:06:21,223 - stages.py[DEBUG]: Running module install-hotplug (<module 'cloudinit.config.cc_install_hotplug' from '/usr/lib/python3/dist-packages/cloudinit/config/cc_install_hotplug.py'>) with frequency once-per-instance
2021-12-07 11:06:21,224 - handlers.py[DEBUG]: start: modules-final/config-install-hotplug: running config-install-hotplug with frequency once-per-instance
2021-12-07 11:06:21,224 - util.py[DEBUG]: Writing to /var/lib/cloud/instances/9d5276fc-2736-a348-9ee7-95af558790ea/sem/config_install_hotplug - wb: [644] 25 bytes
2021-12-07 11:06:21,225 - helpers.py[DEBUG]: Running config-install-hotplug using lock (<FileLock using file '/var/lib/cloud/instances/9d5276fc-2736-a348-9ee7-95af558790ea/sem/config_install_hotplug'>)
2021-12-07 11:06:21,226 - stages.py[DEBUG]: Allowed events: {<EventScope.NETWORK: 'network'>: {<EventType.BOOT_NEW_INSTANCE: 'boot-new-instance'>, <EventType.BOOT: 'boot'>}}
2021-12-07 11:06:21,226 - stages.py[DEBUG]: Event Denied: scopes=['network'] EventType=hotplug
2021-12-07 11:06:21,226 - cc_install_hotplug.py[DEBUG]: Skipping hotplug install, not enabled
2021-12-07 11:06:21,226 - handlers.py[DEBUG]: finish: modules-final/config-install-hotplug: SUCCESS: config-install-hotplug ran successfully
2021-12-07 11:06:21,226 - stages.py[DEBUG]: Running module phone-home (<module 'cloudinit.config.cc_phone_home' from '/usr/lib/python3/dist-packages/cloudinit/config/cc_phone_home.py'>) with frequency once-per-instance
2021-12-07 11:06:21,242 - handlers.py[DEBUG]: start: modules-final/config-phone-home: running config-phone-home with frequency once-per-instance
2021-12-07 11:06:21,242 - util.py[DEBUG]: Writing to /var/lib/cloud/instances/9d5276fc-2736-a348-9ee7-95af558790ea/sem/config_phone_home - wb: [644] 25 bytes
2021-12-07 11:06:21,243 - helpers.py[DEBUG]: Running config-phone-home using lock (<FileLock using file '/var/lib/cloud/instances/9d5276fc-2736-a348-9ee7-95af558790ea/sem/config_phone_home'>)
2021-12-07 11:06:21,243 - cc_phone_home.py[DEBUG]: Skipping module named phone-home, no 'phone_home' configuration found
2021-12-07 11:06:21,243 - handlers.py[DEBUG]: finish: modules-final/config-phone-home: SUCCESS: config-phone-home ran successfully
2021-12-07 11:06:21,243 - stages.py[DEBUG]: Running module final-message (<module 'cloudinit.config.cc_final_message' from '/usr/lib/python3/dist-packages/cloudinit/config/cc_final_message.py'>) with frequency always
2021-12-07 11:06:21,294 - handlers.py[DEBUG]: start: modules-final/config-final-message: running config-final-message with frequency always
2021-12-07 11:06:21,294 - helpers.py[DEBUG]: Running config-final-message using lock (<cloudinit.helpers.DummyLock object at 0x7fbd655dda58>)
2021-12-07 11:06:21,295 - util.py[DEBUG]: Reading from /proc/uptime (quiet=False)
2021-12-07 11:06:21,295 - util.py[DEBUG]: Read 11 bytes from /proc/uptime
2021-12-07 11:06:21,299 - util.py[DEBUG]: Cloud-init v. 21.4-0ubuntu1~18.04.1 finished at Tue, 07 Dec 2021 11:06:21 +0000. Datasource DataSourceAzure [seed=/dev/sr0].  Up 30.53 seconds
2021-12-07 11:06:21,299 - util.py[DEBUG]: Writing to /var/lib/cloud/instance/boot-finished - wb: [644] 67 bytes
2021-12-07 11:06:21,300 - handlers.py[DEBUG]: finish: modules-final/config-final-message: SUCCESS: config-final-message ran successfully
2021-12-07 11:06:21,300 - stages.py[DEBUG]: Running module power-state-change (<module 'cloudinit.config.cc_power_state_change' from '/usr/lib/python3/dist-packages/cloudinit/config/cc_power_state_change.py'>) with frequency once-per-instance
2021-12-07 11:06:21,300 - handlers.py[DEBUG]: start: modules-final/config-power-state-change: running config-power-state-change with frequency once-per-instance
2021-12-07 11:06:21,301 - util.py[DEBUG]: Writing to /var/lib/cloud/instances/9d5276fc-2736-a348-9ee7-95af558790ea/sem/config_power_state_change - wb: [644] 25 bytes
2021-12-07 11:06:21,301 - helpers.py[DEBUG]: Running config-power-state-change using lock (<FileLock using file '/var/lib/cloud/instances/9d5276fc-2736-a348-9ee7-95af558790ea/sem/config_power_state_change'>)
2021-12-07 11:06:21,301 - cc_power_state_change.py[DEBUG]: no power_state provided. doing nothing
2021-12-07 11:06:21,301 - handlers.py[DEBUG]: finish: modules-final/config-power-state-change: SUCCESS: config-power-state-change ran successfully
2021-12-07 11:06:21,301 - main.py[DEBUG]: Ran 24 modules with 0 failures
2021-12-07 11:06:21,302 - atomic_helper.py[DEBUG]: Atomically writing to file /var/lib/cloud/data/status.json (via temporary file /var/lib/cloud/data/tmp5mhalgcw) - w: [644] 587 bytes/chars
2021-12-07 11:06:21,302 - atomic_helper.py[DEBUG]: Atomically writing to file /var/lib/cloud/data/result.json (via temporary file /var/lib/cloud/data/tmpq15migrq) - w: [644] 82 bytes/chars
2021-12-07 11:06:21,303 - util.py[DEBUG]: Creating symbolic link from '/run/cloud-init/result.json' => '../../var/lib/cloud/data/result.json'
2021-12-07 11:06:21,303 - util.py[DEBUG]: Reading from /proc/uptime (quiet=False)
2021-12-07 11:06:21,303 - util.py[DEBUG]: Read 11 bytes from /proc/uptime
2021-12-07 11:06:21,303 - util.py[DEBUG]: cloud-init mode 'modules' took 0.287 seconds (0.28)
2021-12-07 11:06:21,303 - handlers.py[DEBUG]: HyperVReportingHandler flushing remaining events
2021-12-07 11:06:21,303 - handlers.py[DEBUG]: finish: modules-final: SUCCESS: running modules for final
